Workbook
Name Ac: #REF!
Name Als: [1]Menu!$HQ$8
Name Ap: [1]Menu!$GN$13
Name As: #REF!
Name Ash: #REF!
Name Ashs: [1]Menu!$HQ$20
Name Astrs: [1]Menu!$HQ$13
Name Astsel: [1]Menu!$HQ$25
Name b: CALCUL!$C$70
Name bc: CALCUL!$C$29
Name Bw: [2]Sayfa1!$M$18
Name Co: CALCUL!$C$27
Name cv: #REF!
Name d: CALCUL!$E$29
Name DIAM: CALCUL!$C$7:$C$8
Name DIAMETRE: CALCUL!$B$7:$B$8
Name disposition: "Picture 2,Picture 4"
Name dp: CALCUL!$E$70
Name Duct: #REF!
Name DynamicList: OFFSET([3]Enveloppe!$I$31,0,0,COUNTA([3]Enveloppe!$I$31:$I$60),1)
Name fc: #REF!
Name fVc: [1]Menu!$GJ$16
Name fy: #REF!
Name h: CALCUL!$D$70
Name hc: CALCUL!$D$29
Name Hcr: #REF!
Name hk: #REF!
Name Hu: [1]Menu!$EB$16
Name Hv: [2]Sayfa1!$M$16
Name k: #REF!
Name k1_: #REF!
Name k1dizi: #REF!
Name k2_: #REF!
Name L: [1]Menu!$KZ$19
Name Lcl: CALCUL!$F$27
Name Lcr: CALCUL!$D$27
Name lcrp: CALCUL!$H$70
Name liste: [4]Feuil4!$B$3:$B$4
Name Lrec: CALCUL!$E$27
Name Lrp: CALCUL!$B$70
Name Lu: #REF!
Name Lucr: #REF!
Name Lw: [2]Sayfa1!$M$17
Name m: #REF!
Name m_x: #REF!
Name m_y: #REF!
Name mmin: #REF!
Name Mu: [1]Menu!$EB$22
Name Mx: [2]Sayfa1!$AQ$26
Name Mxd: #REF!
Name My: [2]Sayfa1!$AQ$27
Name Myd: #REF!
Name n: #REF!
Name Nd: [2]Sayfa1!$AQ$23
Name Ndmax: [1]Menu!$GN$10
Name pic: "Picture 2,Picture 4"
Name Ppull: [1]Menu!$IR$16
Name Qa: [1]Menu!$FL$10
Name qusf: [1]Menu!$FG$29
Name S: CALCUL!$F$70

Sheet POTEAUX 
D2: ARMATURE TRANSVERSALE D'UNE POTEAUX [ BAEL91 + RPA2024]
D3: R.P.A 2024 | E3: =CALCUL!$C$3 -> Vers 2,00
D5: CALCUL ÉSPACEMENT & DIAMÈTRE DES CADRES
D6: Sens | F6: Y - Y | G6: Z - Z
D7: Zone sismique | F7: I
D8: Fe (Mpa) | F8: 400
D9: Fc28 (Mpa) | F9: 25 | H9: ="Asmin = "&IF(OR(F7="I",F7="II"),0.8%*F12*G12,IF(F7="III",0.9%*F12*G12,1%*F12*G12))&" cm²" -> Asmin = 12.8 cm²
D10: Фlmin (cm) | F10: 1.6
D11: Lcl (m) | F11: 5.2
D12: bc (cm) ; hc (cm) | F12: 40 | G12: 40
D13: d1;d2 (cm) | F13: 3
D14: VU (KN) | F14: 15 | G14: 15
D15: At min (cm²) | E15: At (cm²) Choisi | F15: øt (cm) Choisi | G15: Nbrins
D16: =CALCUL!G20 -> 1.2 | E16: =G16*F16^2*PI()/4 -> 6.2831853 | F16: 1 | G16: 8
D17: λ g | F17: =CALCUL!C16 -> 9.1 | G17: =CALCUL!C17 -> 9.1
D18: ρa | F18: =CALCUL!D16 -> 2.5 | G18: =CALCUL!D17 -> 2.5
D19: St max (cm) | E19: Zone nodale | F19: =CALCUL!G12 -> 12.5
E20: Zone courante | F20: =CALCUL!H12 -> 24
D21: St choisi (cm) | E21: Zone nodale | F21: 10
E22: Zone courante | F22: 20
D23: =IF(AND(E16>=D16,F21<=F19,F22<=F20),"Condition vérifiée","Condition non vérifiée") -> Condition vérifiée
D24: =IF(E16<D16," Remarque : La quantité d'armatures transversales choisie est inférieure à la quantité minimale",IF(F22>F20,"Remarque : L'espacement choisi sur la zone courante dépasse l'espacement calculé",IF(F21>F19,"Remarque : L'espacement choisi sur la zone nodale dépasse l'espacement calculé"," ")))
D26: Vérification des sollicitations tangentes
D27: Sens Y - Y | F27: Sens Z - Z
D28: λg | E28: =$F$17 -> 9.1 | F28: λg | G28: =$G$17 -> 9.1
D29: ρd | E29: =IF(E28>=5,0.075,0.04) -> 0.075 | F29: ρd | G29: =IF(G28>=5,0.075,0.04) -> 0.075
D30: τbu (Mpa) | E30: =E29*F9 -> 1.875 | F30: τbu (Mpa) | G30: =F9*G29 -> 1.875
D31: Ty (KN) | E31: =F14 -> 15 | F31: Tz (KN) | G31: =G14 -> 15
D32: τ (Mpa) | E32: =E31*10/(F12*0.9*G12) -> 0.10416667 | F32: τ (Mpa) | G32: =G31*10/(G12*0.9*F12) -> 0.10416667
D33: Condition | E33: =IF(E32<=E30,"OK","C.N.V") -> OK | F33: Condition | G33: =IF(G32<=G30,"OK","C.N.V") -> OK

Sheet POUTRES
B2: ARMATURE TRANSVERSALE D'UNE POUTRE [ BAEL 91 mod. 99 + RPA2024]
B3: R.P.A 2024 | C3: =CALCUL!$C$3 -> Vers 2,00
B5: CALCUL ESPACEMENT & DIAMETRE DES CADRES | G5: VERIFICATION D'UNE POUTRE A L'EFFORT TRANCHANT | L5: VERIFICATIONS DE LA TORSION
B6: b (cm) ; h (cm) | D6: 30 | E6: 35 | G6: VU (KN) | I6: =D12 -> 47.82 | L6: b (cm) ; h (cm) | N6: 30 | O6: 35
B7: d1;d2 (cm) | D7: 2.5 | G7: Zone sismique | I7: IV | L7: Fissuration | N7: Fissuration peu nuisible
B8: Fe (Mpa) | D8: 400 | G8: Fissuration | I8: Fissuration peu nuisible | L8: Fe (Mpa) | N8: 500
B9: Fc28 (Mpa) | D9: 25 | G9: a (cm) | I9: 50 | L9: Fc28 (Mpa) | N9: 25
B10: Фlmin (cm) | D10: 1.4 | G10: As (inférieure) (cm²) | I10: 10 | L10: VU (KN) | N10: 47.82
B11: Les armatures comprimées | D11: Non nécessaire | G11: Vérification de la contrainte tangente limite ultime | L11: TU (KN.m) | N11: 9.825
B12: VU (KN) | D12: 47.82 | G12: τu (Mpa) | H12: τuadm (Mpa) | I12: VERIFICATION | L12: At (cm²) Choisi | N12: øt (cm) Choisi | O12: Nbrins
B13: At min (cm²) | C13: At (cm²) Choisi | D13: øt (cm) Choisi | E13: Nbrins | G13: =CALCUL!B55 -> 0.50603175 | H13: =CALCUL!C55 -> 3.3333333 | I13: =IF(G13<=H13,"Condition vérifiée","Condition non vérifiée") -> Condition vérifiée | L13: =O13*N13^2*PI()/4 -> 1.0053096 | N13: 0.8 | O13: 2
B14: =MAX((0.003*D18*D6),MIN(E6/35,D10,D6/10)) -> 1 | C14: =E14*D14^2*PI()/4 -> 2.0106193 | D14: 0.8 | E14: 4 | G14: Vérification de la contrainte de compression (bielle) | L14: e (cm) | N14: =N6/6 -> 5
B15: St max (cm) | C15: Zone nodale | D15: =CALCUL!$G$45 -> 8.4 | G15: VU (KN) | H15: 0,267.b.a.fc28 (KN) | I15: VERIFICATION | L15: Ω (cm²) | N15: =(N6-N14)*(O6-N14) -> 750
C16: Zone courante | D16: =CALCUL!$H$45 -> 17.5 | G16: =CALCUL!B59 -> 47.82 | H16: =CALCUL!C59 -> 911.1375 | I16: =IF(G16<=H16,"Condition vérifiée","Condition non vérifiée") -> Condition vérifiée | L16: μ (cm) | N16: =((N6-N14)+(O6-N14))*2 -> 110
B17: St choisi (cm) | C17: Zone nodale | D17: 8 | G17: Vérification des armatures inférieures d'appuis | L17: tUV (Mpa) | N17: =(N10*1000)/((N6*10)*((O6-(O6/10))*10)) -> 0.50603175
C18: Zone courante | D18: 10 | G18: As (cm2) | H18: Vu/(fe/ϒs) (cm2) | I18: VERIFICATION | L18: tUT (Mpa) | N18: =(N11*1000)/(2*N15*N14) -> 1.31
B19: =IF(AND(CALCUL!C39>=(0.003*D18*D6),D18<=D16,D17<=D15),"Condition vérifiée","Condition non vérifiée") -> Condition vérifiée | G19: =CALCUL!B63 -> 10 | H19: =CALCUL!C63 -> 1.374825 | I19: =IF(G19>=H19,"Condition vérifiée","Condition non vérifiée") -> Condition vérifiée | L19: tlim (Mpa) | N19: =IF(N7="Fissuration peu nuisible",MIN(0.2*N9/1.5,5),MIN(0.15*N9/1.5,4)) -> 3.3333333
B20: =IF(C14<(0.003*D18*D6)," Remarque : La quantité d'armatures transversales choisie est inférieure à la quantité minimale ",IF(D18>D16,"Remarque : L'espacement choisi sur la zone courante dépasse l'espacement maximale",IF(D17>D15,"Remarque : L'espacement choisi sur la zone nodale dépasse l'espacement maximale"," "))) | G20: Vérification de la contrainte moyenne de compression | L20: VERIFICATION | N20: =IF((N17^2+N18^2)<=N19^2,"Condition vérifiée","Condition non vérifiée") -> Condition vérifiée
G21: σmb (MPa) | H21: 1,3 Fc28 /ϒb | I21: VERIFICATION | L21: Al (cm²) | N21: =N16*N11*1000/(2*N15*N8/1.15) -> 1.65715
G22: =CALCUL!C67 -> 0.70065934 | H22: =CALCUL!D67 -> 21.666667 | I22: =IF(G22<=H22,"Condition vérifiée","Condition non vérifiée") -> Condition vérifiée | L22: St (cm) | N22: =(2*N15*L13)/(N11*1000)*(N8/1.15) -> 66.731474
D24: ="Asmin= "&(0.5%*D6*E6)&" cm²" -> Asmin= 5.25 cm²

Sheet About
B3: Si vous remarquez une erreur ou avez une remarque, n’hésitez pas à me contacter par e-mail ou sur mon compte Telegram. | H3: hammoutota@gmail.com
H4: https://t.me/MorsliHammou

Sheet CALCUL
A2: CALCUL POTEAUX [ BAEL91 + RPA2024]
A3: R.P.A 2024 | C3: Vers 2,00
B5: Zone | C5: bc (cm) | D5: hc (cm) | E5: Lcl (m) | F5: d1;d2
B6: ='POTEAUX '!F7 -> I | C6: ='POTEAUX '!F12 -> 40 | D6: ='POTEAUX '!G12 -> 40 | E6: ='POTEAUX '!F11 -> 5.2 | F6: ='POTEAUX '!$F$13 -> 3
B7: Фlmin(cm) | C7: fe (Mpa) | D7: fc28 (Mpa) | E7: Vuy(KN) | F7: Vuz(KN)
B8: ='POTEAUX '!F10 -> 1.6 | C8: ='POTEAUX '!F8 -> 400 | D8: ='POTEAUX '!F9 -> 25 | E8: ='POTEAUX '!F14 -> 15 | F8: ='POTEAUX '!G14 -> 15
C10: St max | D10: St max | G10: St max
C11: ZONE NODALE | D11: ZONE COURANTE | G11: ZONE NODALE | H11: ZONE COURANTE
B12: Zone I; II; III | C12: =MIN(10*'POTEAUX '!F10,12.5) -> 12.5 | D12: =15*'POTEAUX '!F10 -> 24 | G12: =IF(OR($B$6="I",$B$6="II",$B$6="III"),C12,C13) -> 12.5 | H12: =IF(OR($B$6="I",$B$6="II",$B$6="III"),D12,D13) -> 24
B13: Zone IV; V; VI | C13: =MIN(('POTEAUX '!F12-2*'POTEAUX '!F13)/3,6*'POTEAUX '!F10,10) -> 9.6 | D13: =MIN('POTEAUX '!F12/2,'POTEAUX '!G12/2,10*'POTEAUX '!F10) -> 16
C15: λg | D15: ρa | E15: At (cm²)
B16: Sens bc | C16: =E6*0.7/(C6/100) -> 9.1 | D16: =IF(C16>=5,2.5,3.75) -> 2.5 | E16: =(D16*E8*'POTEAUX '!F21)*10^3/(C6*C8*10^2) -> 0.234375
B17: Sens hc | C17: =E6*0.7/(D6/100) -> 9.1 | D17: =IF(C17>=5,2.5,3.75) -> 2.5 | E17: =(D17*F8*'POTEAUX '!F21)*10^3/(D6*C8*10^2) -> 0.234375
C19: % | D19: At min (cm²) | G19: At (cm²) min
B20: Sens bc | C20: {=IF(C16>=5,0.3%,IF(C16<=3,0.8%,FORECAST(C16,C23:C24,D23:D24)))} -> 0.003 | D20: =C20*C6*'POTEAUX '!F21 -> 1.2 | G20: =MAX(E16,D20,E17,D21) -> 1.2
B21: Sens hc | C21: {=IF(C17>=5,0.3%,IF(C17<=3,0.8%,FORECAST(C17,C23:C24,D23:D24)))} -> 0.003 | D21: =C21*D6*'POTEAUX '!F21 -> 1.2
C23: 0.008 | D23: 3
C24: 0.003 | D24: 5
C26: 50Øl (cm) | D26: Lcr (cm) | E26: Lrecouvrement (cm) | F26: Lcl (cm) | G26: t (cm) | H26: t' (cm)
C27: ="50Øl = "&50*'POTEAUX '!$F$10&" (cm) " -> 50Øl = 80 (cm) | D27: ="Lcr = "&ROUND(MAX(1.5*'POTEAUX '!G12,'POTEAUX '!F11*100/6,60),2)&" (cm)" -> Lcr = 86,67 (cm) | E27: ="Lrec = "&IF(OR('POTEAUX '!$F$7="I",'POTEAUX '!$F$7="II",'POTEAUX '!$F$7="III"),50*B8,60*B8)& "(cm)" -> Lrec = 80(cm) | F27: ="Lcl = "&$E$6&" (m)" -> Lcl = 5,2 (m) | G27: ="t = "&'POTEAUX '!F21&" (cm)" -> t = 10 (cm) | H27: ="t' = "&'POTEAUX '!F22&" (cm)" -> t' = 20 (cm)
C28: bc (cm) | D28: hc (cm) | E28: d1;d2 (cm)
C29: ="bc = "&$C$6&" (cm)" -> bc = 40 (cm) | D29: ="hc = "&$D$6&" (cm)" -> hc = 40 (cm) | E29: ="d = "&$F$6&" (cm)" -> d = 3 (cm)
A31: CALCUL POUTRES [ BAEL91 + RPA2024]
A32: R.P.A 2024 | C32: Vers 1.0
B34: Calcul éspacement & diamètre des cadres
C36: τu (Mpa) | D36: ft28 (Mpa)
C37: =(POUTRES!D12*1000)/((POUTRES!D6*10)*((POUTRES!E6-(POUTRES!E6/10))*10)) -> 0.50603175 | D37: =0.6+(0.06*POUTRES!D9) -> 2.1
C38: At calculé(cm2) | D38: Фt (cm)
C39: =POUTRES!C14 -> 2.0106193 | D39: =POUTRES!D14 -> 0.8
C41: St | D41: St
C42: =(0.9*C39*POUTRES!D8)/(1.15*POUTRES!D6*(C37-(0.3*D37))) -> -169.2399 | D42: =IF(C42<0,100,C42) -> 100
C43: ZONE NODALE | D43: ZONE COURANTE | G43: St max
A44: BAEL | B44: min⁡(0,9*d , 40 cm) | C44: =MIN(0.9*POUTRES!E6,40) -> 31.5 | D44: =MIN(0.9*POUTRES!E6,40) -> 31.5 | G44: ZONE NODALE | H44: ZONE COURANTE
A45: BAEL | B45: (At*0.9*fe)/(b*γs*(τu-0.3*ft28 ) ) | C45: =D42 -> 100 | D45: =D42 -> 100 | G45: =MIN(C44:C47) -> 8.4 | H45: =MIN(D44:D47) -> 17.5
A46: BAEL | B46: (At*fe)/(b*0.4) | C46: =(C39*POUTRES!D8)/(0.4*POUTRES!D6) -> 67.020643 | D46: =C46 -> 67.020643
A47: RPA2024 | B47: min⁡(h/4; 24Æt; 17.5 cm;6Æl ) | h/2 | C47: =MIN(POUTRES!E6/4,24*D39,17.5,6*POUTRES!D10) -> 8.4 | D47: =IF(POUTRES!D11="Sont nécessaires",MIN(POUTRES!E6/4,12*POUTRES!D10),POUTRES!E6/2) -> 17.5
B50: Vérification d'une poutre à l'éffort tranchant
B53: Vérification de la contrainte tangente limite ultime
B54: τu (Mpa) | C54: τu adm(Mpa) | D54: Vérification
B55: =(POUTRES!I6*1000)/((POUTRES!D6*10)*((POUTRES!E6-(POUTRES!E6/10))*10)) -> 0.50603175 | C55: =IF(POUTRES!I8="Fissuration peu nuisible",MIN(0.2*POUTRES!D9/1.5,5),MIN(0.15*POUTRES!D9/1.5,4)) -> 3.3333333 | D55: =IF(B55<=C55,"OK","Condition non vérifiée") -> OK
...
