Workbook
Name Ac: #REF!
Name Als: [1]Menu!$HQ$8
Name Ap: [1]Menu!$GN$13
Name As: #REF!
Name Ash: #REF!
Name Ashs: [1]Menu!$HQ$20
Name Astrs: [1]Menu!$HQ$13
Name Astsel: [1]Menu!$HQ$25
Name Bw: [2]Sayfa1!$M$18
Name cv: #REF!
Name Duct: #REF!
Name DynamicList: OFFSET(Enveloppe!$I$31,0,0,COUNTA(Enveloppe!$I$31:$I$56),1)
Name fc: #REF!
Name fVc: [1]Menu!$GJ$16
Name fy: #REF!
Name Hcr: #REF!
Name hk: #REF!
Name Hu: [1]Menu!$EB$16
Name Hv: [2]Sayfa1!$M$16
Name k: #REF!
Name k1_: #REF!
Name k1dizi: #REF!
Name k2_: #REF!
Name L: [1]Menu!$KZ$19
Name Lu: #REF!
Name Lucr: #REF!
Name Lw: [2]Sayfa1!$M$17
Name m: #REF!
Name m_x: #REF!
Name m_y: #REF!
Name mmin: #REF!
Name Mu: [1]Menu!$EB$22
Name Mx: [2]Sayfa1!$AQ$26
Name Mxd: #REF!
Name My: [2]Sayfa1!$AQ$27
Name Myd: #REF!
Name n: #REF!
Name Nd: [2]Sayfa1!$AQ$23
Name Ndmax: [1]Menu!$GN$10
Name Ppull: [1]Menu!$IR$16
Name Qa: [1]Menu!$FL$10
Name qusf: [1]Menu!$FG$29
Name setmax: [1]Menu!$FL$18
Name step1: #REF!
Name step2: #REF!
Name step3: #REF!
Name step4: #REF!
Name step5: #REF!
Name Vd: #REF!
Name Ve: #REF!
Name Vr: #REF!
Name VrVe: #REF!
Name Vx: [2]Sayfa1!$AQ$24
Name Vy: [2]Sayfa1!$AQ$25
Name Yu: [1]Menu!$EB$30
Name α: #REF!
Name μ: #REF!

Sheet  Données
B2: DONNE POUR CALCUL LE FERRAILLAGE DES VOILLES
B3: R.P.A 2024 | C3: Vers 1.2 | E3: =Calcul!$C$2 -> Vers 1.5.3
D5: N étages | E5: hw (m) | F5: he (m) | G5: lw (m) | H5: bw (m) | I5: d1,2 (cm) | J5: Fc28 (Mpa) | K5: Fe (Mpa) | L5: γb | M5: γs
D6: 5 | E6: 15.3 | F6: 2.61 | G6: 1.6 | H6: 0.2 | I6: 2.5 | J6: 25 | K6: 400 | L6: 1.2 | M6: 1
D7: Type de systèm
D8: 4- Système à contreventement mixte, équivalent à des voiles
D9: Qf | E9: T0 (s) | F9: T2 (s) | G9: Nimax [KN] | H9: R | I9: Type de voile
D10: 1 | E10: 0.52 | F10: 0.25 | G10: 663.8 | H10: =Calcul!$M$106 -> 4.5 | I10: =IF($E$6/$G$6<=2/3,"VOILES DE GRANDES DIMENSIONS ",IF($E$6/$G$6<=2,"VOILES COURTS","VOILES ELANCES")) -> VOILES ELANCES
D11: ENVELOPPE DE CALCUL POUR LES MOMENTS FLECHISSANT
D12: =IF(Calcul!J75="OUI","Il est nécessaire de modifier les moments fléchissants résultant du calcul de structure","il n 'est pas necessaire de modifier les moments flechissants, resultant du calcul de structure") -> Il est nécessaire de modifier les moments fléchissants résultant du calcul de structure
D13: ENVELOPPE DE CALCUL POUR LES EFFORTS TRANCHANTS
D14: =IF(Calcul!E75="OUI","Il est nécessaire de modifier les efforts tranchants résultant du calcul de structure","Il n’est pas nécessaire de modifier les efforts tranchants résultant du calcul de structure") -> Il est nécessaire de modifier les efforts tranchants résultant du calcul de structure
D16: Niveau | E16: Hi [m] | F16: Ni [KN] | G16: Mi [KN.m] | H16: Ti [KN] | N16: =' Données'!E6&" m" -> 15.3 m
C17: 0 | D17: =IF(C17<=$D$6,C17," ") -> 0 | E17: 0 | F17: -600.51 | G17: -144.03 | H17: 112.5 | N17: Zone superieure
C18: 1 | D18: =IF(C18<=$D$6,C18," ") -> 1 | E18: 3.06 | F18: -365.4 | G18: -44.76 | H18: 51.27
C19: 2 | D19: =IF(C19<=$D$6,C19," ") -> 2 | E19: 6.12 | F19: -250.31 | G19: -8.74 | H19: 45.64
C20: 3 | D20: =IF(C20<=$D$6,C20," ") -> 3 | E20: 9.18 | F20: -91.82 | G20: 6.28 | H20: 39.33
C21: 4 | D21: =IF(C21<=$D$6,C21," ") -> 4 | E21: 12.24 | F21: -16.33 | G21: 49.64 | H21: 41.69
C22: 5 | D22: =IF(C22<=$D$6,C22," ") -> 5 | E22: 15.3 | F22: -49.18 | G22: -32.21 | H22: 42.06
C23: 6 | D23: =IF(C23<=$D$6,C23," ")
C24: 7 | D24: =IF(C24<=$D$6,C24," ") | N24: =Calcul!S73 &" m" -> 6.12 m
C25: 8 | D25: =IF(C25<=$D$6,C25," ") | N25: Au-dessus de la zone critique
C26: 9 | D26: =IF(C26<=$D$6,C26," ")
C27: 10 | D27: =IF(C27<=$D$6,C27," ")
C28: 11 | D28: =IF(C28<=$D$6,C28," ")
C29: 12 | D29: =IF(C29<=$D$6,C29," ")
C30: 13 | D30: =IF(C30<=$D$6,C30," ")
C31: 14 | D31: =IF(C31<=$D$6,C31," ") | N31: =Calcul!Q73&" m" -> 3.06 m
C32: 15 | D32: =IF(C32<=$D$6,C32," ") | N32: Zone critique
C33: 16 | D33: =IF(C33<=$D$6,C33," ")
C34: 17 | D34: =IF(C34<=$D$6,C34," ")
C35: 18 | D35: =IF(C35<=$D$6,C35," ")
C36: 19 | D36: =IF(C36<=$D$6,C36," ")
C37: 20 | D37: =IF(C37<=$D$6,C37," ")
C38: 21 | D38: =IF(C38<=$D$6,C38," ") | N38: 0.00 m
C39: 22 | D39: =IF(C39<=$D$6,C39," ")
C40: 23 | D40: =IF(C40<=$D$6,C40," ")
C41: 24 | D41: =IF(C41<=$D$6,C41," ")
C42: 25 | D42: =IF(C42<=$D$6,C42," ")

Sheet Enveloppe
E2: ENVELOPPE DE CALCUL POUR LES MOMENTS FLECHISSANT
E3: R.P.A 2024 | G3: =Calcul!$C$2 -> Vers 1.5.3
I5: Nombre d'étages | J5: =' Données'!$D$6 -> 5
I6: he (m) | J6: =' Données'!$F$6 -> 2.61
I7: lw (m) | J7: =' Données'!$G$6 -> 1.6
I8: hw (m) | J8: =' Données'!$E$6 -> 15.3
I9: Moment à la base | J9: =' Données'!$G$17 -> -144.03
I10: Moment au sommet | J10: {=INDEX(' Données'!G17:G41,MATCH(' Données'!$E$6,' Données'!E17:E41,1))} -> -32.21
I11: hcr1 [7,22] | J11: =MAX(J7,J8/6) -> 2.55
I12: hcritique (m) | J12: =ROUND(IF(J11<=MIN(2*J7,IF(J5<=6,J6,2*J6)),J11,MIN(2*J7,IF(J5<=6,J6,2*J6))),2) -> 2.55
I14: Hi [m] | J14: 5
I15: Mi [KN,m] | J15: =Calcul!G34 -> 126.12418
G17: =IF($J$14>$J$8,"Remarque : H = " & $J$14&" > hw = "&$J$8," ")
E22: ENVELOPPE DE CALCUL POUR LES EFFORTS TRANCHANTS
E23: R.P.A 2024 | G23: =Calcul!$C$2 -> Vers 1.5.3
G25: =IF(COUNTIF(I31:I56,">0")<>J26,"Remarque : Vérifiée le nombre des étages", " ")
H26: Nombre d'étages | J26: =$J$5 -> 5
H27: Hi [m] | J27: 6.12
H28: Ti [KN] | J28: =Calcul!$J$48 -> -67.746
H30: Niveau | I30: Hi Cumulées [m] | J30: Ti [KN]
H31: =' Données'!D17 -> 0 | I31: =IF(H31=" "," ",' Données'!E17) -> 0 | J31: =IF(H31=" "," ",' Données'!H17) -> 112.5
H32: =' Données'!D18 -> 1 | I32: =IF(H32=" "," ",' Données'!E18) -> 3.06 | J32: =IF(H32=" "," ",' Données'!H18) -> 51.27
H33: =' Données'!D19 -> 2 | I33: =IF(H33=" "," ",' Données'!E19) -> 6.12 | J33: =IF(H33=" "," ",' Données'!H19) -> 45.64
H34: =' Données'!D20 -> 3 | I34: =IF(H34=" "," ",' Données'!E20) -> 9.18 | J34: =IF(H34=" "," ",' Données'!H20) -> 39.33
H35: =' Données'!D21 -> 4 | I35: =IF(H35=" "," ",' Données'!E21) -> 12.24 | J35: =IF(H35=" "," ",' Données'!H21) -> 41.69
H36: =' Données'!D22 -> 5 | I36: =IF(H36=" "," ",' Données'!E22) -> 15.3 | J36: =IF(H36=" "," ",' Données'!H22) -> 42.06
H37: =' Données'!D23 | I37: =IF(H37=" "," ",' Données'!E23) | J37: =IF(H37=" "," ",' Données'!H23)
H38: =' Données'!D24 | I38: =IF(H38=" "," ",' Données'!E24) | J38: =IF(H38=" "," ",' Données'!H24)
H39: =' Données'!D25 | I39: =IF(H39=" "," ",' Données'!E25) | J39: =IF(H39=" "," ",' Données'!H25)
H40: =' Données'!D26 | I40: =IF(H40=" "," ",' Données'!E26) | J40: =IF(H40=" "," ",' Données'!H26)
H41: =' Données'!D27 | I41: =IF(H41=" "," ",' Données'!E27) | J41: =IF(H41=" "," ",' Données'!H27)
H42: =' Données'!D28 | I42: =IF(H42=" "," ",' Données'!E28) | J42: =IF(H42=" "," ",' Données'!H28)
... H56: =' Données'!D42 | I56: =IF(H56=" "," ",' Données'!E42) | J56: =IF(H56=" "," ",' Données'!H42)

Sheet Zone critique
B2: FERRAILLAGE DES VOILLES DE LA ZONE CRITIQUE
B3: R.P.A 2024 | C3: =Calcul!$C$2 -> Vers 1.5.3
B5: DONNEES
B6: he (m) | C6: lw (m) | D6: bw (m) | E6: d1,2 (cm) | F6: Fc28 (Mpa) | G6: Fe (Mpa) | H6: γb | I6: γs | J6: hcr (m) | K6: R | L6: Qf | M6: T0 (s) | N6: T2 (s) | O6: N (KN) | P6: MED (KN,m) | Q6: Ṽ (KN) | R6: MRD (KN,m)
B7: =' Données'!$F$6 -> 2.61 | C7: =' Données'!$G$6 -> 1.6 | D7: =' Données'!$H$6 -> 0.2 | E7: =' Données'!$I$6 -> 2.5 | F7: =' Données'!$J$6 -> 25 | G7: =' Données'!$K$6 -> 400 | H7: =' Données'!$L$6 -> 1.2 | I7: =' Données'!$M$6 -> 1 | J7: =Enveloppe!$J$12 -> 2.55 | K7: =' Données'!$H$10 -> 4.5 | L7: =' Données'!$D$10 -> 1 | M7: =' Données'!$E$10 -> 0.52 | N7: =' Données'!$F$10 -> 0.25 | O7: =ABS(Calcul!G79) -> 600.51 | P7: =Calcul!$H$79 -> 144.03 | Q7: =ABS(Calcul!$I$79) -> 157.5 | R7: ='Moment resistant'!$B$38*1 -> 981.90514
B9: ELEMENT DE RIVE GOUCHE | E9: =" d (cm)= "&$E$7 -> d (cm)= 2.5 | F9: =IF(C12>C14,B14& " = "&$C$12,B14& " = "&$C$14) -> Lcg (min) (cm) = 35 | H9: St (cm) = 50 | J9: ="Lâme (cm) = "&$C$7*100-$C$12-$R$12-4*$E$7 -> Lâme (cm) = 80 | L9: ="bw(cm) = "&$D$7*100 -> bw(cm) = 20 | M9: =IF(R12>R14,Q14& "= "&$R$12,Q14& "= "&R14) -> Lcd (min) (cm)= 35 | O9: =" d (cm)= "&$E$7 -> d (cm)= 2.5 | Q9: ELEMENT DE RIVE DROITE
B10: Ølmin (cm) | C10: 1.2 | F10: =B15&" = "&C13 -> bcg (min) (cm) = 20 | O10: =Q15&" = "&R13 -> bcd (min) (cm) = 20 | Q10: Ølmin (cm) | R10: 1.2
B11: Avcalc (cm²) | C11: 9.05 | Q11: Avcalc (cm²) | R11: 9.05
B12: Lc.choisi (cm) | C12: 35 | Q12: lc.choisi (cm) | R12: 35
B13: bc.choisi (cm) | C13: 20 | Q13: bc.choisi (cm) | R13: 20
B14: Lcg (min) (cm) | C14: =ROUND(MAX(0.15*$C$7,1.5*$D$7),2)*100 -> 30 | Q14: Lcd (min) (cm) | R14: =ROUND(MAX(0.15*$C$7,1.5*$D$7),2)*100 -> 30
B15: bcg (min) (cm) | C15: =MAX(IF($C$12/100>MAX(2*$D$7,0.2*$C$7),$B$7/10,$B$7/15),0.2)*100 -> 20 | Q15: bcd (min) (cm) | R15: =MAX(IF($R$12/100> MAX(2*$D$7,0.2*$C$7),$B$7/10,$B$7/15),0.2)*100 -> 20
B16: b0 (cm) | C16: =$C$13-2*$E$7 -> 15 | F16: =B19&" = "&C19 -> Avg (cm²) = 9.05 | H16: =B23&"= "&C23 -> At (cm²)= 0.74 | J16: =C6&" = " &C7 -> lw (m) = 1.6 | M16: =Q19&" = "&R19 -> Avd (cm²) = 9.05 | Q16: b0 (cm) | R16: =$R$13-2*$E$7 -> 15
B17: Avmin (cm²) | C17: =0.5%*($C$12+2*$E$7)*$C$13 -> 4 | Q17: Avmin (cm²) | R17: =0.5%*($R$12+2*$E$7)*$R$13 -> 4
B18: Avj (cm²) | C18: =1.1*($Q$7*10)/$G$7 -> 4.33125 | I18: ="Ø"&$J$28*10 -> Ø10 | J18: ="St= "&$J$29 -> St= 20 | L18: ="Ø"&$M$28*10 -> Ø12 | Q18: Avj (cm²) | R18: =1.1*($Q$7*10)/$G$7 -> 4.33125
B19: Avg (cm²) | C19: =MAX($C$11,$C$17,$C$18) -> 9.05 | Q19: Avd (cm²) | R19: =MAX($R$11,$R$17,$R$18) -> 9.05
B20: Stmax (cm) | C20: =FLOOR(MIN($C$16/3,12.5,6*$C$10),1) -> 5 | Q20: Stmax (cm) | R20: =FLOOR(MIN($R$16/3,12.5,6*$R$10),1) -> 5
B21: Ag (cm²) | C21: =($C$12+2*$E$7)*$C$13 -> 800 | I21: =" Sh = "&M29 -> Sh = 20 | Q21: Ag (cm²) | R21: =($R$12+2*$E$7)*$R$13 -> 800
B22: Ac (cm²) | C22: =$C$12*$C$16 -> 525 | O22: ="St"&"= "&R20 &"cm" -> St= 5cm | Q22: Ac (cm²) | R22: =$R$12*$R$16 -> 525
B23: At (cm²) | C23: =ROUND(MAX((0.09*$C$20*$C$16*$F$7/$G$7),(0.3*$C$20*$C$16*(($C$21/$C$22)-1)*$F$7/$G$7)),2) -> 0.74 | Q23: At (cm²) | R23: =MAX((0.09*$R$20*$R$16*$F$7/$G$7),(0.3*$R$20*$R$16*(($R$21/$R$22)-1)*$F$7/$G$7)) -> 0.73660714
B24: =IF(OR($C$12+$R$12+4*$E$7>=$C$7*100,2*$C$12>=$C$7*100),"- Augmenter la longueur du voile ou diminuer la longueur Lc."&CHAR(10)," ")& IF($C$13<$C$15,"- bc,choisi < bcg (min)."," ") & IF($C$12<$C$14,"-Lc,choisi < Lcg (min)."," ") | Q24: =IF(OR($R$12+$C$12+4*$E$7>=$C$7*100,2*$R$12>=$C$7*100),"- Augmenter la longueur du voile ou diminuer la longueur Lc."&CHAR(10)," ")& IF($R$13<$R$15,"- bc,choisi < bcg (min)."," ") & IF($R$12<$R$14,"- Lc,choisi < Lcg (min)."," ")
H26: L'AME
H27: L'AME (aciers verticaux) | K27: L'AME (aciers horizontaux)
H28: Øl (cm) | J28: 1 | K28: Øl (cm) | M28: 1.2
H29: Svchoisi (cm) | J29: 20 | K29: Shchoisi (cm) | M29: 20
H30: Svmax (cm) | J30: =MIN(1.5*$D$7*100,25,25*$J$28) -> 25 | K30: Shmax (cm) | M30: =MIN(25,25*$J$28) -> 25
H31: Ølmin (cm) | J31: =0.8 -> 0.8 | K31: Z (cm) | M31: =$C$7*100-$C$12/2-$R$12/2-2*$E$7 -> 120
H32: Ølmax (cm) | J32: =$D$7*100/8 -> 2.5 | K32: Ølmax (cm) | M32: =$D$7*100/8 -> 2.5
H33: ="Avmin (cm²)/e="&$J$29&"cm" -> Avmin (cm²)/e=20cm | J33: =ROUND(0.2%*$J$29*$D$7*100,2) -> 0.8 | K33: ="Ahmin (cm²)/e="&$M$29&"cm" -> Ahmin (cm²)/e=20cm | M33: =ROUND(MAX(($M$29*ABS(' Données'!$H$17)*1.4)/($M$31*$G$7)*10,0.2%*$M$29*$D$7*100),2) -> 0.8
H34: ="Asv (cm²)/L ="&($C$7*100-$C$12-$R$12-4*$E$7)&"cm" -> Asv (cm²)/L =80cm | J34: =(CEILING(($C$7*100-$C$12-$R$12-4*$E$7)/$J$29,1)*(PI()*$J$28^2/4))*2 -> 6.2831853 | K34: ="Ash (cm²)/h ="&$J$7*100&"cm" -> Ash (cm²)/h =255cm | M34: =(CEILING(J7*100/M29,1)*(PI()*M28^2/4))*2 -> 29.405307
H35: =IF(Calcul!$P$75<=Calcul!$Q$75,Calcul!P74&" = "&Calcul!$P$75&" < "&Calcul!Q74&" = "&Calcul!$Q$75,Calcul!P74&" ="&Calcul!$P$75&"> "&Calcul!Q74&" = "&Calcul!$Q$75) -> τb (MPa) = 0.55 < τadm (MPa) = 5 | L35: =IF(Calcul!$P$75<=Calcul!$Q$75,"Condition vérifie ","Condition non vérifie ") -> Condition vérifie
H36: =IF($J$29<=$J$30," ","Sv,choisi > Sv,max") | K36: =IF($M$29<=$M$30," ","Sh,choisi > Sh,max")&IF((2*PI()*$M$28^2/4<$M$33),"Ahchoisi"&" < Ahmin"," ")
B38: CONDITIONS DE DUCTILITE LOCALE
B40: ELEMENT DE RIVE GOUCHE | E40: ELEMENT GOUCHE | N40: ELEMENT DROITE | Q40: ELEMENT DE RIVE DROITE
B41: nd (KN) | C41: =ROUND(ABS(' Données'!$G$10)*10^3/((($C$12*10*$C$13*10)+($R$12*10*$R$13*10)+(($C$7*10^3-$C$12*10-$R$12*10)*$D$7*10^3))*$F$7),2) -> 0.08 | E41: n | F41: 8 | N41: n | O41: 8 | Q41: nd (KN) | R41: =ROUND(ABS(' Données'!$G$10)*10^3/((($C$12*10*$C$13*10)+($R$12*10*$R$13*10)+(($C$7*10^3-$C$12*10-$R$12*10)*$D$7*10^3))*$F$7),2) -> 0.08
B42: Fyd/Fcd | C42: =($G$7/$F$7)*($H$7/$I$7) -> 19.2 | E42: bi (cm) | F42: 12 | N42: bi (cm) | O42: 12 | Q42: Fyd/Fcd | R42: =($G$7/$F$7)*($H$7/$I$7) -> 19.2
B43: wn | C43: =ROUND((($J$34/(($C$7*100-2*$C$12)*$D$7*100)))*$C$42,2) -> 0.07 | E43: L (cm) | F43: 184 | N43: L (cm) | O43: 184 | Q43: wn | R43: =ROUND((($J$34/(($C$7*100-2*R12)*$D$7*100)))*R42,2) -> 0.07
B44: cu | C44: =($C$41+$C$43)*($C$7*100*$C$13)/($C$16) -> 32 | E44: Øl (cm) | F44: 0.8 | N44: Øl (cm) | O44: 0.8 | Q44: cu | R44: =($R$41+$R$43)*($C$7*100*$R$13)/($R$16) -> 32
B45: Vnc (cm³) | C45: =$C$12*$C$16*$J$7*100 -> 133875 | E45: Nnbr | F45: =FLOOR(($J$7*100-10)/$C$20,1) -> 49 | N45: Nnbr | O45: =FLOOR(($J$7*100-10)/$R$20,1) -> 49 | Q45: Vnc (cm³) | R45: =$R$12*$R$16*$J$7*100 -> 133875
B46: Vst (cm³) | C46: =$F$43*(PI()*($F$44^2)/4)*$F$45 -> 4531.9359 | E46: St (cm) | F46: =$C$20 -> 5 | N46: St (cm) | O46: =$R$20 -> 5 | Q46: Vst (cm³) | R46: =$O$43*(PI()*($O$44^2)/4)*$O$45 -> 4531.9359
...

Sheet Zone supèrieure
D2: FERRAILLAGE DES VOILLES DE LA ZONE SUPERIEURE
D3: R.P.A 2024 | E3: =Calcul!$C$2 -> Vers 1.5.3
D5: L'AME (Zone supèrieure)
D7: L'AME (aciers verticaux) | G7: L'AME (aciers horizontaux)
D8: Øl (cm) | F8: 1 | G8: Øl (cm) | I8: 1
D9: Stchoisi (cm) | F9: 20 | G9: Stchoisi (cm) | I9: 25
D10: Ølmax (cm) | F10: =Calcul!$F$73*100/10 -> 2 | G10: Ølmax (cm) | I10: =Calcul!$F$73*100/10 -> 2
D11: Stmax (cm) | F11: =MIN(1.5*Calcul!$F$73*100,25,25*$F$8) -> 25 | G11: Stmax (cm) | I11: =MIN(1.5*Calcul!$F$73*100,25) -> 25
I14: ELEMENTS DE RIVE | L14: L'AME
A15: Zone critique | D15: Niveau | E15: Hi [m] | F15: Ni [KN] | G15: Mi [KN.m] | H15: Ti [KN] | I15: Asv (cm²) | J15: Asvmin (cm²) | K15: Choix des barres | L15: ="Avmin (cm²)"&CHAR(10)&" e = "&F9&" cm" -> Avmin (cm²) e = 20 cm | M15: ="Choix des barres"&CHAR(10)&"n HA"&$F$8*10&"/e= "&$F$9&" cm" -> Choix des barres n HA10/e= 20 cm | N15: Ah (cm²) | O15: ="Ahmin (cm²)"&CHAR(10)&" e = "&I9&" cm" -> Ahmin (cm²) e = 25 cm | P15: ="Choix des barres"&CHAR(10)&"n HA"&$I$8*10&"/e= "&$I$9&" cm" -> Choix des barres n HA10/e= 25 cm | Q15: Zone
A16: =Calcul!Q73 -> 3.06 | D16: =Calcul!E79 -> 0 | E16: =Calcul!F79 -> 0 | F16: =Calcul!G79 -> -600.51 | G16: =Calcul!H79 -> 144.03 | H16: =Calcul!I79 -> -157.5 | J16: =IF(E16=" "," ",Calcul!O79) -> 3.5 | L16: =IF(E16=" "," ",0.2%*$F$9*' Données'!$H$6*100) -> 0.8 | M16: =Calcul!R124 -> 2HA10=1.57cm² | N16: =IF(E16=" "," ",($I$9*ABS(' Données'!H17)*1.4/('Zone critique'!$M$31*' Données'!$K$6)*10)) -> 0.8203125 | O16: =IF(E16=" "," ",0.2%*$I$9*' Données'!$H$6*100) -> 1 | P16: =Calcul!S124 -> 2HA10=1.57cm² | Q16: =IF(E16=" ", " ",IF(E16<=$A$16, "Zone critique(déjà calculée)",IF(E16=$A$19,"Au-dessus de la zone critique", "Zone superieure"))) -> Zone critique(déjà calculée)
A17: Au-dessus de la zone critique | D17: =Calcul!E80 -> 1 | E17: =Calcul!F80 -> 3.06 | F17: =Calcul!G80 -> -365.4 | G17: =Calcul!H80 -> 140.30267 | H17: =Calcul!I80 -> -71.778 | J17: =IF(E17=" "," ",Calcul!O80) -> 3.5 | L17: =IF(E17=" "," ",0.2%*$F$9*' Données'!$H$6*100) -> 0.8 | M17: =Calcul!R125 -> 2HA10=1.57cm² | N17: =IF(E17=" "," ",($I$9*ABS(' Données'!H18)*1.4/('Zone critique'!$M$31*' Données'!$K$6)*10)) -> 0.37384375 | O17: =IF(E17=" "," ",0.2%*$I$9*' Données'!$H$6*100) -> 1 | P17: =Calcul!S125 -> 2HA10=1.57cm² | Q17: =IF(E17=" ", " ",IF(E17<=$A$16, "Zone critique(déjà calculée)",IF(E17=$A$19,"Au-dessus de la zone critique", "Zone superieure"))) -> Zone critique(déjà calculée)
D18: =Calcul!E81 -> 2 | E18: =Calcul!F81 -> 6.12 | F18: =Calcul!G81 -> -250.31 | G18: =Calcul!H81 -> 117.93867 | H18: =Calcul!I81 -> -67.746 | I18: 0 | J18: =IF(E18=" "," ",Calcul!O81) -> 3.5 | K18: 8HA12 = 9.05 | L18: =IF(E18=" "," ",0.2%*$F$9*' Données'!$H$6*100) -> 0.8 | M18: =Calcul!R126 -> 2HA10=1.57cm² | N18: =IF(E18=" "," ",($I$9*ABS(' Données'!H19)*1.4/('Zone critique'!$M$31*' Données'!$K$6)*10)) -> 0.33279167 | O18: =IF(E18=" "," ",0.2%*$I$9*' Données'!$H$6*100) -> 1 | P18: =Calcul!S126 -> 2HA10=1.57cm² | Q18: =IF(E18=" ", " ",IF(E18<=$A$16, "Zone critique(déjà calculée)",IF(E18=$A$19,"Au-dessus de la zone critique", "Zone superieure"))) -> Au-dessus de la zone critique
A19: =Calcul!$S$73 -> 6.12 | D19: =Calcul!E82 -> 3 | E19: =Calcul!F82 -> 9.18 | F19: =Calcul!G82 -> -91.82 | G19: =Calcul!H82 -> 95.574667 | H19: =Calcul!I82 -> -71.414 | I19: 0.37 | J19: =IF(E19=" "," ",Calcul!O82) -> 3.5 | K19: 8HA12 = 9.05 | L19: =IF(E19=" "," ",0.2%*$F$9*' Données'!$H$6*100) -> 0.8 | M19: =Calcul!R127 -> 2HA10=1.57cm² | N19: =IF(E19=" "," ",($I$9*ABS(' Données'!H20)*1.4/('Zone critique'!$M$31*' Données'!$K$6)*10)) -> 0.28678125 | O19: =IF(E19=" "," ",0.2%*$I$9*' Données'!$H$6*100) -> 1 | P19: =Calcul!S127 -> 2HA10=1.57cm² | Q19: =IF(E19=" ", " ",IF(E19<=$A$16, "Zone critique(déjà calculée)",IF(E19=$A$19,"Au-dessus de la zone critique", "Zone superieure"))) -> Zone superieure
D20: =Calcul!E83 -> 4 | E20: =Calcul!F83 -> 12.24 | F20: =Calcul!G83 -> -16.33 | G20: =Calcul!H83 -> 73.210667 | H20: =Calcul!I83 -> -75.082 | I20: 0.96 | J20: =IF(E20=" "," ",Calcul!O83) -> 3.5 | K20: 8HA12 = 9.05 | L20: =IF(E20=" "," ",0.2%*$F$9*' Données'!$H$6*100) -> 0.8 | M20: =Calcul!R128 -> 2HA10=1.57cm² | N20: =IF(E20=" "," ",($I$9*ABS(' Données'!H21)*1.4/('Zone critique'!$M$31*' Données'!$K$6)*10)) -> 0.30398958 | O20: =IF(E20=" "," ",0.2%*$I$9*' Données'!$H$6*100) -> 1 | P20: =Calcul!S128 -> 2HA10=1.57cm² | Q20: =IF(E20=" ", " ",IF(E20<=$A$16, "Zone critique(déjà calculée)",IF(E20=$A$19,"Au-dessus de la zone critique", "Zone superieure"))) -> Zone superieure
D21: =Calcul!E84 -> 5 | E21: =Calcul!F84 -> 15.3 | F21: =Calcul!G84 -> -49.18 | G21: =Calcul!H84 -> 50.846667 | H21: =Calcul!I84 -> -78.75 | I21: 0.19 | J21: =IF(E21=" "," ",Calcul!O84) -> 3.5 | K21: 8HA12 = 9.05 | L21: =IF(E21=" "," ",0.2%*$F$9*' Données'!$H$6*100) -> 0.8 | M21: =Calcul!R129 -> 2HA10=1.57cm² | N21: =IF(E21=" "," ",($I$9*ABS(' Données'!H22)*1.4/('Zone critique'!$M$31*' Données'!$K$6)*10)) -> 0.3066875 | O21: =IF(E21=" "," ",0.2%*$I$9*' Données'!$H$6*100) -> 1 | P21: =Calcul!S129 -> 2HA10=1.57cm² | Q21: =IF(E21=" ", " ",IF(E21<=$A$16, "Zone critique(déjà calculée)",IF(E21=$A$19,"Au-dessus de la zone critique", "Zone superieure"))) -> Zone superieure
D22: =Calcul!E85 | E22: =Calcul!F85 | F22: =Calcul!G85 | G22: =Calcul!H85 | H22: =Calcul!I85 | J22: =IF(E22=" "," ",Calcul!O85) | L22: =IF(E22=" "," ",0.2%*$F$9*' Données'!$H$6*100) | M22: =Calcul!R130 | N22: =IF(E22=" "," ",($I$9*ABS(' Données'!H23)*1.4/('Zone critique'!$M$31*' Données'!$K$6)*10)) | O22: =IF(E22=" "," ",0.2%*$I$9*' Données'!$H$6*100) | P22: =Calcul!S130 | Q22: =IF(E22=" ", " ",IF(E22<=$A$16, "Zone critique(déjà calculée)",IF(E22=$A$19,"Au-dessus de la zone critique", "Zone superieure")))
D23: =Calcul!E86 | E23: =Calcul!F86 | F23: =Calcul!G86 | G23: =Calcul!H86 | H23: =Calcul!I86 | J23: =IF(E23=" "," ",Calcul!O86) | L23: =IF(E23=" "," ",0.2%*$F$9*' Données'!$H$6*100) | M23: =Calcul!R131 | N23: =IF(E23=" "," ",($I$9*ABS(' Données'!H24)*1.4/('Zone critique'!$M$31*' Données'!$K$6)*10)) | O23: =IF(E23=" "," ",0.2%*$I$9*' Données'!$H$6*100) | P23: =Calcul!S131 | Q23: =IF(E23=" ", " ",IF(E23<=$A$16, "Zone critique(déjà calculée)",IF(E23=$A$19,"Au-dessus de la zone critique", "Zone superieure")))
D24: =Calcul!E87 | E24: =Calcul!F87 | F24: =Calcul!G87 | G24: =Calcul!H87 | H24: =Calcul!I87 | J24: =IF(E24=" "," ",Calcul!O87) | L24: =IF(E24=" "," ",0.2%*$F$9*' Données'!$H$6*100) | M24: =Calcul!R132 | N24: =IF(E24=" "," ",($I$9*ABS(' Données'!H25)*1.4/('Zone critique'!$M$31*' Données'!$K$6)*10)) | O24: =IF(E24=" "," ",0.2%*$I$9*' Données'!$H$6*100) | P24: =Calcul!S132 | Q24: =IF(E24=" ", " ",IF(E24<=$A$16, "Zone critique(déjà calculée)",IF(E24=$A$19,"Au-dessus de la zone critique", "Zone superieure")))
D25: =Calcul!E88 | E25: =Calcul!F88 | F25: =Calcul!G88 | G25: =Calcul!H88 | H25: =Calcul!I88 | J25: =IF(E25=" "," ",Calcul!O88) | L25: =IF(E25=" "," ",0.2%*$F$9*' Données'!$H$6*100) | M25: =Calcul!R133 | N25: =IF(E25=" "," ",($I$9*ABS(' Données'!H26)*1.4/('Zone critique'!$M$31*' Données'!$K$6)*10)) | O25: =IF(E25=" "," ",0.2%*$I$9*' Données'!$H$6*100) | P25: =Calcul!S133 | Q25: =IF(E25=" ", " ",IF(E25<=$A$16, "Zone critique(déjà calculée)",IF(E25=$A$19,"Au-dessus de la zone critique", "Zone superieure")))
D26: =Calcul!E89 | E26: =Calcul!F89 | F26: =Calcul!G89 | G26: =Calcul!H89 | H26: =Calcul!I89 | J26: =IF(E26=" "," ",Calcul!O89) | L26: =IF(E26=" "," ",0.2%*$F$9*' Données'!$H$6*100) | M26: =Calcul!R134 | N26: =IF(E26=" "," ",($I$9*ABS(' Données'!H27)*1.4/('Zone critique'!$M$31*' Données'!$K$6)*10)) | O26: =IF(E26=" "," ",0.2%*$I$9*' Données'!$H$6*100) | P26: =Calcul!S134 | Q26: =IF(E26=" ", " ",IF(E26<=$A$16, "Zone critique(déjà calculée)",IF(E26=$A$19,"Au-dessus de la zone critique", "Zone superieure")))
D27: =Calcul!E90 | E27: =Calcul!F90 | F27: =Calcul!G90 | G27: =Calcul!H90 | H27: =Calcul!I90 | J27: =IF(E27=" "," ",Calcul!O90) | L27: =IF(E27=" "," ",0.2%*$F$9*' Données'!$H$6*100) | M27: =Calcul!R135 | N27: =IF(E27=" "," ",($I$9*ABS(' Données'!H28)*1.4/('Zone critique'!$M$31*' Données'!$K$6)*10)) | O27: =IF(E27=" "," ",0.2%*$I$9*' Données'!$H$6*100) | P27: =Calcul!S135 | Q27: =IF(E27=" ", " ",IF(E27<=$A$16, "Zone critique(déjà calculée)",IF(E27=$A$19,"Au-dessus de la zone critique", "Zone superieure")))
D28: =Calcul!E91 | E28: =Calcul!F91 | F28: =Calcul!G91 | G28: =Calcul!H91 | H28: =Calcul!I91 | J28: =IF(E28=" "," ",Calcul!O91) | L28: =IF(E28=" "," ",0.2%*$F$9*' Données'!$H$6*100) | M28: =Calcul!R136 | N28: =IF(E28=" "," ",($I$9*ABS(' Données'!H29)*1.4/('Zone critique'!$M$31*' Données'!$K$6)*10)) | O28: =IF(E28=" "," ",0.2%*$I$9*' Données'!$H$6*100) | P28: =Calcul!S136 | Q28: =IF(E28=" ", " ",IF(E28<=$A$16, "Zone critique(déjà calculée)",IF(E28=$A$19,"Au-dessus de la zone critique", "Zone superieure")))
D29: =Calcul!E92 | E29: =Calcul!F92 | F29: =Calcul!G92 | G29: =Calcul!H92 | H29: =Calcul!I92 | J29: =IF(E29=" "," ",Calcul!O92) | L29: =IF(E29=" "," ",0.2%*$F$9*' Données'!$H$6*100) | M29: =Calcul!R137 | N29: =IF(E29=" "," ",($I$9*ABS(' Données'!H30)*1.4/('Zone critique'!$M$31*' Données'!$K$6)*10)) | O29: =IF(E29=" "," ",0.2%*$I$9*' Données'!$H$6*100) | P29: =Calcul!S137 | Q29: =IF(E29=" ", " ",IF(E29<=$A$16, "Zone critique(déjà calculée)",IF(E29=$A$19,"Au-dessus de la zone critique", "Zone superieure")))
D30: =Calcul!E93 | E30: =Calcul!F93 | F30: =Calcul!G93 | G30: =Calcul!H93 | H30: =Calcul!I93 | J30: =IF(E30=" "," ",Calcul!O93) | L30: =IF(E30=" "," ",0.2%*$F$9*' Données'!$H$6*100) | M30: =Calcul!R138 | N30: =IF(E30=" "," ",($I$9*ABS(' Données'!H31)*1.4/('Zone critique'!$M$31*' Données'!$K$6)*10)) | O30: =IF(E30=" "," ",0.2%*$I$9*' Données'!$H$6*100) | P30: =Calcul!S138 | Q30: =IF(E30=" ", " ",IF(E30<=$A$16, "Zone critique(déjà calculée)",IF(E30=$A$19,"Au-dessus de la zone critique", "Zone superieure")))
D31: =Calcul!E94 | E31: =Calcul!F94 | F31: =Calcul!G94 | G31: =Calcul!H94 | H31: =Calcul!I94 | J31: =IF(E31=" "," ",Calcul!O94) | L31: =IF(E31=" "," ",0.2%*$F$9*' Données'!$H$6*100) | M31: =Calcul!R139 | N31: =IF(E31=" "," ",($I$9*ABS(' Données'!H32)*1.4/('Zone critique'!$M$31*' Données'!$K$6)*10)) | O31: =IF(E31=" "," ",0.2%*$I$9*' Données'!$H$6*100) | P31: =Calcul!S139 | Q31: =IF(E31=" ", " ",IF(E31<=$A$16, "Zone critique(déjà calculée)",IF(E31=$A$19,"Au-dessus de la zone critique", "Zone superieure")))
D32: =Calcul!E95 | E32: =Calcul!F95 | F32: =Calcul!G95 | G32: =Calcul!H95 | H32: =Calcul!I95 | J32: =IF(E32=" "," ",Calcul!O95) | L32: =IF(E32=" "," ",0.2%*$F$9*' Données'!$H$6*100) | M32: =Calcul!R140 | N32: =IF(E32=" "," ",($I$9*ABS(' Données'!H33)*1.4/('Zone critique'!$M$31*' Données'!$K$6)*10)) | O32: =IF(E32=" "," ",0.2%*$I$9*' Données'!$H$6*100) | P32: =Calcul!S140 | Q32: =IF(E32=" ", " ",IF(E32<=$A$16, "Zone critique(déjà calculée)",IF(E32=$A$19,"Au-dessus de la zone critique", "Zone superieure")))
D33: =Calcul!E96 | E33: =Calcul!F96 | F33: =Calcul!G96 | G33: =Calcul!H96 | H33: =Calcul!I96 | J33: =IF(E33=" "," ",Calcul!O96) | L33: =IF(E33=" "," ",0.2%*$F$9*' Données'!$H$6*100) | M33: =Calcul!R141 | N33: =IF(E33=" "," ",($I$9*ABS(' Données'!H34)*1.4/('Zone critique'!$M$31*' Données'!$K$6)*10)) | O33: =IF(E33=" "," ",0.2%*$I$9*' Données'!$H$6*100) | P33: =Calcul!S141 | Q33: =IF(E33=" ", " ",IF(E33<=$A$16, "Zone critique(déjà calculée)",IF(E33=$A$19,"Au-dessus de la zone critique", "Zone superieure")))
... D36: =Calcul!E99 | E36: =Calcul!F99 | F36: =Calcul!G99 | G36: =Calcul!H99 | H36: =Calcul!I99 | J36: =IF(E36=" "," ",Calcul!O99) | L36: =IF(E36=" "," ",0.2%*$F$9*' Données'!$H$6*100) | M36: =Calcul!R144 | N36: =IF(E36=" "," ",($I$9*ABS(' Données'!H37)*1.4/('Zone critique'!$M$31*' Données'!$K$6)*10)) | O36: =IF(E36=" "," ",0.2%*$I$9*' Données'!$H$6*100) | P36: =Calcul!S144 | Q36: =IF(E36=" ", " ",IF(E36<=$A$16, "Zone critique(déjà calculée)",IF(E36=$A$19,"Au-dessus de la zone critique", "Zone superieure")))

Sheet Calcul
A2: R.P.A 2024 | C2: Vers 1.5.3
A3: Type de voile
N5: Type 1
N6: Type 2
N7: Type 3
A10: ENVELOPPE DE CALCUL POUR LES MOMENTS FLECHISSANT
F15: Enveloppe Linéaire
F16: M (KN,m) | G16: Hw (m)
F17: 0 | G17: =Enveloppe!$J$8 -> 15.3
F18: =ABS(Enveloppe!$J$10) -> 32.21 | G18: =Enveloppe!$J$8 -> 15.3
F19: =ABS(Enveloppe!$J$9) -> 144.03 | G19: 0
F21: Enveloppe de Calcul 1
F22: M (KN,m) | G22: Hw (m)
F23: =F18 -> 32.21 | G23: =G18+Enveloppe!$J$12 -> 17.85
F24: =F19 -> 144.03 | G24: =G19+Enveloppe!$J$12 -> 2.55
F25: Enveloppe de Calcul
D26: Math | F26: M (KN,m) | G26: Hw (m)
D27: =DEGREES(ATAN(G17/(F19-F18))) -> 7.791231 | F27: 0 | G27: =G17 -> 15.3
D28: =90-D27 -> 82.208769 | F28: =FORECAST(G17,F23:F24,G23:G24) -> 50.846667 | G28: =G18+G13 -> 15.3
D29: =Enveloppe!$J$12*TAN(RADIANS(Calcul!D28)) -> 18.636667 | F29: =F19 -> 144.03 | G29: =Enveloppe!$J$12 -> 2.55
D30: =F18+D29 -> 50.846667 | F30: =F19 -> 144.03 | G30: =G19 -> 0
F32: hcr [7,23] | G32: =Enveloppe!$J$12 -> 2.55
F33: H (m) | G33: =Enveloppe!$J$14 -> 5
F34: M (KN,m) | G34: {=IF($G$33<=$G$32,$F$24,FORECAST(Enveloppe!$J$14,F23:F24,G23:G24))} -> 126.12418
A38: ENVELOPPE DE CALCUL POUR LES EFFORTS TRANCHANTS
B40: Diagramme issue de l'analyse | F40: 1,4 x Vu | I40: Hw (m) | J40: Hw/3 | L40: Diagramme amplifié
B41: Etage | C41: Hw (m) | D41: T (KN) | F41: Hw (m) | G41: T (KN) | I41: =MAX(Enveloppe!I31:I56) -> 15.3 | J41: =I41/3 -> 5.1 | L41: Hw (m) | M41: T (KN)
B42: 0 | C42: =IF(Enveloppe!H31<=Enveloppe!$J$26,Enveloppe!I31,NA()) -> 0 | D42: =IF(Enveloppe!H31<=Enveloppe!$J$26,ABS(Enveloppe!J31)*(-1),NA()) -> -112.5 | F42: =IF(Enveloppe!H31<=Enveloppe!$J$26,Enveloppe!I31,NA()) -> 0 | G42: =IF(Enveloppe!H31<=Enveloppe!$J$26,D42*1.4,NA()) -> -157.5 | L42: {=IF(F42<$J$41,F42,IF(AND(F42>=$J$41,F42<$I$41),$J$41,$I$41))} -> 0 | M42: {=IF(L42>=$I$41,$G$42/2,IF(COUNTIF($F$42:$F$67,L42),INDEX($G$42:$G$67,MATCH(L42,$F$42:$F$67,0)),$J$43))} -> -157.5
B43: 1 | C43: =IF(Enveloppe!H32<=Enveloppe!$J$26,Enveloppe!I32,NA()) -> 3.06 | D43: =IF(Enveloppe!H32<=Enveloppe!$J$26,ABS(Enveloppe!J32)*(-1),NA()) -> -51.27 | F43: =IF(Enveloppe!H32<=Enveloppe!$J$26,Enveloppe!I32,NA()) -> 3.06 | G43: =IF(Enveloppe!H32<=Enveloppe!$J$26,D43*1.4,NA()) -> -71.778 | I43: =$J$41 -> 5.1 | J43: {=FORECAST($J$41,J44:J45,I44:I45)} -> -66.523333 | L43: {=IF(F43<$J$41,F43,IF(AND(F43>=$J$41,F43<$I$41),$J$41,$I$41))} -> 3.06 | M43: {=IF(L43>=$I$41,$G$42/2,IF(COUNTIF($F$42:$F$67,L43),INDEX($G$42:$G$67,MATCH(L43,$F$42:$F$67,0)),$J$43))} -> -71.778
B44: 2 | C44: =IF(Enveloppe!H33<=Enveloppe!$J$26,Enveloppe!I33,NA()) -> 6.12 | D44: =IF(Enveloppe!H33<=Enveloppe!$J$26,ABS(Enveloppe!J33)*(-1),NA()) -> -45.64 | F44: =IF(Enveloppe!H33<=Enveloppe!$J$26,Enveloppe!I33,NA()) -> 6.12 | G44: =IF(Enveloppe!H33<=Enveloppe!$J$26,D44*1.4,NA()) -> -63.896 | I44: {=INDEX(F42:F67,MATCH(J41,F42:F67,1))} -> 3.06 | J44: {=INDEX(G42:G67,MATCH(J41,F42:F67,1))} -> -71.778 | L44: {=IF(F44<$J$41,F44,IF(AND(F44>=$J$41,F44<$I$41),$J$41,$I$41))} -> 5.1 | M44: {=IF(L44>=$I$41,$G$42/2,IF(COUNTIF($F$42:$F$67,L44),INDEX($G$42:$G$67,MATCH(L44,$F$42:$F$67,0)),$J$43))} -> -66.523333
B45: 3 | C45: =IF(Enveloppe!H34<=Enveloppe!$J$26,Enveloppe!I34,NA()) -> 9.18 | D45: =IF(Enveloppe!H34<=Enveloppe!$J$26,ABS(Enveloppe!J34)*(-1),NA()) -> -39.33 | F45: =IF(Enveloppe!H34<=Enveloppe!$J$26,Enveloppe!I34,NA()) -> 9.18 | G45: =IF(Enveloppe!H34<=Enveloppe!$J$26,D45*1.4,NA()) -> -55.062 | I45: {=INDEX(F42:F67,MATCH(J41,F42:F67,1)+1)} -> 6.12 | J45: {=INDEX(G42:G67,MATCH(J41,F42:F67,1)+1)} -> -63.896 | L45: {=IF(F45<$J$41,F45,IF(AND(F45>=$J$41,F45<$I$41),$J$41,$I$41))} -> 5.1 | M45: {=IF(L45>=$I$41,$G$42/2,IF(COUNTIF($F$42:$F$67,L45),INDEX($G$42:$G$67,MATCH(L45,$F$42:$F$67,0)),$J$43))} -> -66.523333
B46: 4 | C46: =IF(Enveloppe!H35<=Enveloppe!$J$26,Enveloppe!I35,NA()) -> 12.24 | D46: =IF(Enveloppe!H35<=Enveloppe!$J$26,ABS(Enveloppe!J35)*(-1),NA()) -> -41.69 | F46: =IF(Enveloppe!H35<=Enveloppe!$J$26,Enveloppe!I35,NA()) -> 12.24 | G46: =IF(Enveloppe!H35<=Enveloppe!$J$26,D46*1.4,NA()) -> -58.366 | L46: {=IF(F46<$J$41,F46,IF(AND(F46>=$J$41,F46<$I$41),$J$41,$I$41))} -> 5.1 | M46: {=IF(L46>=$I$41,$G$42/2,IF(COUNTIF($F$42:$F$67,L46),INDEX($G$42:$G$67,MATCH(L46,$F$42:$F$67,0)),$J$43))} -> -66.523333
B47: 5 | C47: =IF(Enveloppe!H36<=Enveloppe!$J$26,Enveloppe!I36,NA()) -> 15.3 | D47: =IF(Enveloppe!H36<=Enveloppe!$J$26,ABS(Enveloppe!J36)*(-1),NA()) -> -42.06 | F47: =IF(Enveloppe!H36<=Enveloppe!$J$26,Enveloppe!I36,NA()) -> 15.3 | G47: =IF(Enveloppe!H36<=Enveloppe!$J$26,D47*1.4,NA()) -> -58.884 | L47: {=IF(F47<$J$41,F47,IF(AND(F47>=$J$41,F47<$I$41),$J$41,$I$41))} -> 15.3 | M47: {=IF(L47>=$I$41,$G$42/2,IF(COUNTIF($F$42:$F$67,L47),INDEX($G$42:$G$67,MATCH(L47,$F$42:$F$67,0)),$J$43))} -> -78.75
B48: 6 | C48: =IF(Enveloppe!H37<=Enveloppe!$J$26,Enveloppe!I37,NA()) -> #N/A | D48: =IF(Enveloppe!H37<=Enveloppe!$J$26,ABS(Enveloppe!J37)*(-1),NA()) -> #N/A | F48: =IF(Enveloppe!H37<=Enveloppe!$J$26,Enveloppe!I37,NA()) -> #N/A | G48: =IF(Enveloppe!H37<=Enveloppe!$J$26,D48*1.4,NA()) -> #N/A | I48: {=Enveloppe!$J$27} -> 6.12 | J48: {=IF($I$48<=$J$41,INDEX(M42:M67,MATCH($I$48,L42:L67,1)),FORECAST($I$48,J49:J50,I49:I50))} -> -67.746 | L48: {=IF(F48<$J$41,F48,IF(AND(F48>=$J$41,F48<$I$41),$J$41,$I$41))} -> #N/A | M48: {=IF(L48>=$I$41,$G$42/2,IF(COUNTIF($F$42:$F$67,L48),INDEX($G$42:$G$67,MATCH(L48,$F$42:$F$67,0)),$J$43))} -> #N/A
B49: 7 | C49: =IF(Enveloppe!H38<=Enveloppe!$J$26,Enveloppe!I38,NA()) -> #N/A | D49: =IF(Enveloppe!H38<=Enveloppe!$J$26,ABS(Enveloppe!J38)*(-1),NA()) -> #N/A | F49: =IF(Enveloppe!H38<=Enveloppe!$J$26,Enveloppe!I38,NA()) -> #N/A | G49: =IF(Enveloppe!H38<=Enveloppe!$J$26,D49*1.4,NA()) -> #N/A | I49: {=$J$41} -> 5.1 | J49: {=INDEX(M42:M67,MATCH(I49,L42:L67,1))} -> -66.523333 | L49: {=IF(F49<$J$41,F49,IF(AND(F49>=$J$41,F49<$I$41),$J$41,$I$41))} -> #N/A | M49: {=IF(L49>=$I$41,$G$42/2,IF(COUNTIF($F$42:$F$67,L49),INDEX($G$42:$G$67,MATCH(L49,$F$42:$F$67,0)),$J$43))} -> #N/A
B50: 8 | C50: =IF(Enveloppe!H39<=Enveloppe!$J$26,Enveloppe!I39,NA()) -> #N/A | D50: =IF(Enveloppe!H39<=Enveloppe!$J$26,ABS(Enveloppe!J39)*(-1),NA()) -> #N/A | F50: =IF(Enveloppe!H39<=Enveloppe!$J$26,Enveloppe!I39,NA()) -> #N/A | G50: =IF(Enveloppe!H39<=Enveloppe!$J$26,D50*1.4,NA()) -> #N/A | I50: =I41 -> 15.3 | J50: {=INDEX(M42:M67,MATCH(I50,L42:L67,1))} -> -78.75 | L50: {=IF(F50<$J$41,F50,IF(AND(F50>=$J$41,F50<$I$41),$J$41,$I$41))} -> #N/A | M50: {=IF(L50>=$I$41,$G$42/2,IF(COUNTIF($F$42:$F$67,L50),INDEX($G$42:$G$67,MATCH(L50,$F$42:$F$67,0)),$J$43))} -> #N/A
B51: 9 | C51: =IF(Enveloppe!H40<=Enveloppe!$J$26,Enveloppe!I40,NA()) -> #N/A | D51: =IF(Enveloppe!H40<=Enveloppe!$J$26,ABS(Enveloppe!J40)*(-1),NA()) -> #N/A | F51: =IF(Enveloppe!H40<=Enveloppe!$J$26,Enveloppe!I40,NA()) -> #N/A | G51: =IF(Enveloppe!H40<=Enveloppe!$J$26,D51*1.4,NA()) -> #N/A | L51: {=IF(F51<$J$41,F51,IF(AND(F51>=$J$41,F51<$I$41),$J$41,$I$41))} -> #N/A | M51: {=IF(L51>=$I$41,$G$42/2,IF(COUNTIF($F$42:$F$67,L51),INDEX($G$42:$G$67,MATCH(L51,$F$42:$F$67,0)),$J$43))} -> #N/A
B52: 10 | C52: =IF(Enveloppe!H41<=Enveloppe!$J$26,Enveloppe!I41,NA()) -> #N/A | D52: =IF(Enveloppe!H41<=Enveloppe!$J$26,ABS(Enveloppe!J41)*(-1),NA()) -> #N/A | F52: =IF(Enveloppe!H41<=Enveloppe!$J$26,Enveloppe!I41,NA()) -> #N/A | G52: =IF(Enveloppe!H41<=Enveloppe!$J$26,D52*1.4,NA()) -> #N/A | L52: {=IF(F52<$J$41,F52,IF(AND(F52>=$J$41,F52<$I$41),$J$41,$I$41))} -> #N/A | M52: {=IF(L52>=$I$41,$G$42/2,IF(COUNTIF($F$42:$F$67,L52),INDEX($G$42:$G$67,MATCH(L52,$F$42:$F$67,0)),$J$43))} -> #N/A
B53: 11 | C53: =IF(Enveloppe!H42<=Enveloppe!$J$26,Enveloppe!I42,NA()) -> #N/A | D53: =IF(Enveloppe!H42<=Enveloppe!$J$26,ABS(Enveloppe!J42)*(-1),NA()) -> #N/A | F53: =IF(Enveloppe!H42<=Enveloppe!$J$26,Enveloppe!I42,NA()) -> #N/A | G53: =IF(Enveloppe!H42<=Enveloppe!$J$26,D53*1.4,NA()) -> #N/A | L53: {=IF(F53<$J$41,F53,IF(AND(F53>=$J$41,F53<$I$41),$J$41,$I$41))} -> #N/A | M53: {=IF(L53>=$I$41,$G$42/2,IF(COUNTIF($F$42:$F$67,L53),INDEX($G$42:$G$67,MATCH(L53,$F$42:$F$67,0)),$J$43))} -> #N/A
B54: 12 | C54: =IF(Enveloppe!H43<=Enveloppe!$J$26,Enveloppe!I43,NA()) -> #N/A | D54: =IF(Enveloppe!H43<=Enveloppe!$J$26,ABS(Enveloppe!J43)*(-1),NA()) -> #N/A | F54: =IF(Enveloppe!H43<=Enveloppe!$J$26,Enveloppe!I43,NA()) -> #N/A | G54: =IF(Enveloppe!H43<=Enveloppe!$J$26,D54*1.4,NA()) -> #N/A | L54: {=IF(F54<$J$41,F54,IF(AND(F54>=$J$41,F54<$I$41),$J$41,$I$41))} -> #N/A | M54: {=IF(L54>=$I$41,$G$42/2,IF(COUNTIF($F$42:$F$67,L54),INDEX($G$42:$G$67,MATCH(L54,$F$42:$F$67,0)),$J$43))} -> #N/A
...

Sheet Moment resistant
B1: PROJECT : | I1: R. Taleb | J1: Université de Blida 1 | N1: y (cm)
B2: CLIENT : | I2: Ver. 2.0 | J2: Département de Génie Civil
B3: Task ID : | E3: mdification Ing Morsli Hammou | I3: Jan. 2025 | J3: Email: rafik.taleb.dz@gmail.com | N3: -3500
A4: Moment résistant - Section Rectangulaire en BA aux ELU selon CBA 93 | N4: -350
A5: Données de calcul | J5: L'auteur n'est pas résponsable | N5: -35
A6: Caracteristiques des matériaux | J6: de l'utilisation faite de | N6: -31.5
A7: Résistance caracteristique du béton | F7: fc28 | G7: = | H7: =' Données'!J6 -> 25 | I7: Mpa | J7: de ce programme | N7: -28
A8: Limite d'élasticite de l'acier | F8: fe | G8: = | H8: =' Données'!K6 -> 400 | I8: MPa | N8: -24.5
A9: Coefficients | K9: =IF(H7<8,"Revoir fc28","") | L9: =IF(H8<200,"Revoir fe","") | N9: -17.5
A10: Coefficient de durée de chargenent | F10: q = | G10: = | H10: =IF(H11=1.2,0.85,1) -> 0.85 | I10: =IF(H10=1,"> 24h", IF(H10=0.9,"24h> …>1h","< 1h")) -> < 1h | N10: -14
A11: Coefficient de sécurite partiel - Béton | F11: gb = | G11: = | H11: =' Données'!$L$6 -> 1.2 | N11: -10.5
A12: Coefficient de sécurite partiel - Acier | F12: gs = | G12: = | H12: =' Données'!$M$6 -> 1 | N12: -7
A13: Effort normal | N13: -3.5
A14: Effort normal ultime | F14: Nu | G14: = | H14: ='Zone critique'!O7 -> 600.51 | I14: kN | K14: =IF(OR(H14<'CALCUL Mrd'!H32,H14>'CALCUL Mrd'!H33),"Effort N > Nultime !!","") | N14: 0
A15: Section et Ferraillage | N15: 0.35000002
A16: Largeur du poteau | F16: b | G16: = | H16: ='Zone critique'!$D$7*100 -> 20 | I16: cm | N16: 0.70000005
A17: Hauteur du poteau | F17: h | G17: = | H17: ='Zone critique'!$C$7*100 -> 160 | I17: cm | N17: 1.05
A18: Section des armatures tendues (Sup.) | F18: As | G18: = | H18: ='Zone critique'!$C$19 -> 9.05 | I18: cm² | K18: =IF((H18+H20)>4*H16*H17/100,"Revoir ferraillage >4% ","") | N18: 1.4000001
A19: Position cdg armatures tendues (Sup.) | F19: c | G19: = | H19: ='Zone critique'!$E$7 -> 2.5 | I19: cm | M19: Help? Calculer la section d'armatures à introduire
A20: Section des armatures comprimés (Inf.) | F20: Asc | G20: = | H20: ='Zone critique'!$C$19 -> 9.05 | I20: cm² | M20: 4 | N20: HA14 | O20: + | P20: 2 | Q20: HA12 | R20: + | S20: 0 | T20: HA16
A21: Position cdg Armatures comprimés (Inf.) | F21: d' | G21: = | H21: ='Zone critique'!$E$7 -> 2.5 | I21: cm | M21: =M20*VLOOKUP(N20,'CALCUL Mrd'!$C$49:$E$57,3,FALSE) -> 6.1575216 | P21: =P20*VLOOKUP(Q20,'CALCUL Mrd'!$C$49:$E$57,3,FALSE) -> 2.2619467 | S21: =S20*VLOOKUP(T20,'CALCUL Mrd'!$C$49:$E$57,3,FALSE) -> 0
A22: Contrainte de compression du béton | F22: fbu | G22: = | H22: =0.85*H7/H11/H10 -> 20.833333 | I22: Mpa | M22: =M21+P21+S21 -> 8.4194683
A23: Contrainte ultime de l'acier | F23: fsu | G23: = | H23: =H8/H12 -> 400 | I23: Mpa | N23: 3.1500001
N24: 3.5
A25: Analyse | N25: 3.8499999
N26: 4.1999998
N27: 4.5499997
N28: 4.9000001
N29: 5.25
N30: 5.6000004
N31: 5.9500003
N32: 6.3000002
N33: 6.6500001
N34: 7
A35: Résultats | N35: 9.0649996
N36: 10.5
A37: 1- Moment résistant ultime | N37: 14
A38: Mru = | B38: =IF(OR(H14<'CALCUL Mrd'!H32,H14>'CALCUL Mrd'!H33),"N/A",MAX('CALCUL Mrd'!S7:S85)) -> 981.90514 | N38: 17.5
N39: 19.25
A40: 2- Profondeur de l'axe neutre | N40: 21
...

Sheet CALCUL Mrd
J5: Domaine | K5: x (cm) | L5: es1 | M5: sigs1 | N5: es2 | O5: sigs2 | P5: Nu | Q5: Mu | R5: N-app | S5: Mur-cor | T5: x-cor
B6: Coefficient de durée de chargenent | I6: -100 | J6: =IF(K6<=0,"Domaine 1",IF(AND(K6>0,K6<=$H$16*$H$21/($H$21+$H$20)),"Domaine 2",IF(K6<=$H$23,"Domaine 3",IF(K6<=$H$16,"Domaine 4",IF(K6<=$H$11,"Domaine 4a","Domaine 5"))))) -> Domaine 1 | K6: =I6*$H$16 -> -157.5 | L6: =IF(K6<=0,"N/A",IF(K6<=$H$16*$H$21/($H$21+$H$20),"N/A",IF(K6<=$H$23,$H$21 * ($H$16 - K6) /K6,IF(K6<=$H$16,$H$21 * ($H$16 - K6) /K6,IF(K6<=$H$11,$H$21 * (K6-$H$16) /K6,$H$22 * (K6 - $H$16) / (K6 -$H$11 / 2)))))) -> N/A | M6: =IF(L6="N/A","N/A",IF(L6>=0,MIN(L6*$H$17,$H$19),MAX(L6*$H$17,-$H$19))) -> N/A | N6: =IF(K6<=0,$H$20*($H$15-K6)/($H$16-K6),IF(K6<=$H$16*$H$21/($H$21+$H$20),$H$20*(K6-$H$15)/($H$16-K6),IF(K6<=$H$23,$H$20*(K6-$H$15)/K6,IF(K6<=$H$16,$H$20*(K6-$H$15)/K6,IF(K6<=$H$11,$H$20*(K6-$H$15)/K6,$H$22 * (K6 - $H$15) / (K6 - $H$11 / 2)))))) -> 0.0099025617 | O6: =IF(N6>=0,MIN(N6*$H$17,$H$19),MAX(N6*$H$17,-$H$19)) -> 400 | P6: =1000*IF(K6<0,-H$14*(O6-0.8*H$18)-H$12*H$19,IF(K6<=H$16*H$21/(H$21+H$20),0.8*H$18*K6*H$10+H$14*(O6-0.8*H$18)-H$12*H$19,IF(K6<=H$23,0.8*H$18*K6*H$10+H$14*(O6-0.8*H$18)-H$12*M6,IF(K6<=H$16,0.8*H$18*K6*H$10+H$14*(O6-0.8*H$18)-H$12*M6,IF(K6<=H$11,0.8*H$18*K6*H$10+H$14*(O6-0.8*H$18)+H$12*M6,H$18*(1-(1-0.8)*H$11/K6)*H$11*H$10+H$14*(O6-0.8*H$18)+H$12*M6))))) -> -708.91667 | Q6: =1000*IF(K6<0,-H$14*(O6-0.8*H$18)*(H$11/2-H$15)-H$12*H$19*(H$11/2-H$16),IF(K6<=H$16*H$21/(H$21+H$20),0.8*H$18*K6*H$10*(H$11/2-0.8*K6/2)+H$14*(O6-0.8*H$18)*(H$11/2-H$15)-H$12*H$19*(H$11/2-H$16),IF(K6<=H$23,0.8*H$18*K6*H$10*(H$11/2-0.8*K6/2)+H$14*(O6-0.8*H$18)*(H$11/2-H$15)-H$12*M6*(H$11/2-H$16),IF(K6<=H$16,0.8*H$18*K6*H$10*(H$11/2-0.8*K6/2)+H$14*(O6-0.8*H$18)*(H$11/2-H$15)-H$12*M6*(H$11/2-H$16),IF(K6<=H$11,0.8*H$18*K6*H$10*(H$11/2-0.8*K6/2)+H$14*(O6-0.8*H$18)*(H$11/2-H$15)+H$12*M6*(H$11/2-H$16),H$18*(1-(1-0.8)*H$11/K6)*H$11*H$10*(H$11/2 -(1- (1-0.8)*H$11/K6)*H$11/2) + H$14*O6*(H$11/2-H$15)+H$12*M6*(H$11/2-H$16)))))) -> 11.689583 | R6: ='Moment resistant'!$H$14 -> 600.51
B7: 1 | C7: > 24h | I7: -10 | J7: =IF(K7<=0,"Domaine 1",IF(AND(K7>0,K7<=$H$16*$H$21/($H$21+$H$20)),"Domaine 2",IF(K7<=$H$23,"Domaine 3",IF(K7<=$H$16,"Domaine 4",IF(K7<=$H$11,"Domaine 4a","Domaine 5"))))) -> Domaine 1 | K7: =I7*$H$16 -> -15.75 | L7: =IF(K7<=0,"N/A",IF(K7<=$H$16*$H$21/($H$21+$H$20),"N/A",IF(K7<=$H$23,$H$21 * ($H$16 - K7) /K7,IF(K7<=$H$16,$H$21 * ($H$16 - K7) /K7,IF(K7<=$H$11,$H$21 * (K7-$H$16) /K7,$H$22 * (K7 - $H$16) / (K7 -$H$11 / 2)))))) -> N/A | M7: =IF(L7="N/A","N/A",IF(L7>=0,MIN(L7*$H$17,$H$19),MAX(L7*$H$17,-$H$19))) -> N/A | N7: =IF(K7<=0,$H$20*($H$15-K7)/($H$16-K7),IF(K7<=$H$16*$H$21/($H$21+$H$20),$H$20*(K7-$H$15)/($H$16-K7),IF(K7<=$H$23,$H$20*(K7-$H$15)/K7,IF(K7<=$H$16,$H$20*(K7-$H$15)/K7,IF(K7<=$H$11,$H$20*(K7-$H$15)/K7,$H$22 * (K7 - $H$15) / (K7 - $H$11 / 2)))))) -> 0.0091053391 | O7: =IF(N7>=0,MIN(N7*$H$17,$H$19),MAX(N7*$H$17,-$H$19)) -> 400 | P7: =1000*IF(K7<0,-H$14*(O7-0.8*H$18)-H$12*H$19,IF(K7<=H$16*H$21/(H$21+H$20),0.8*H$18*K7*H$10+H$14*(O7-0.8*H$18)-H$12*H$19,IF(K7<=H$23,0.8*H$18*K7*H$10+H$14*(O7-0.8*H$18)-H$12*M7,IF(K7<=H$16,0.8*H$18*K7*H$10+H$14*(O7-0.8*H$18)-H$12*M7,IF(K7<=H$11,0.8*H$18*K7*H$10+H$14*(O7-0.8*H$18)+H$12*M7,H$18*(1-(1-0.8)*H$11/K7)*H$11*H$10+H$14*(O7-0.8*H$18)+H$12*M7))))) -> -708.91667 | Q7: =1000*IF(K7<0,-H$14*(O7-0.8*H$18)*(H$11/2-H$15)-H$12*H$19*(H$11/2-H$16),IF(K7<=H$16*H$21/(H$21+H$20),0.8*H$18*K7*H$10*(H$11/2-0.8*K7/2)+H$14*(O7-0.8*H$18)*(H$11/2-H$15)-H$12*H$19*(H$11/2-H$16),IF(K7<=H$23,0.8*H$18*K7*H$10*(H$11/2-0.8*K7/2)+H$14*(O7-0.8*H$18)*(H$11/2-H$15)-H$12*M7*(H$11/2-H$16),IF(K7<=H$16,0.8*H$18*K7*H$10*(H$11/2-0.8*K7/2)+H$14*(O7-0.8*H$18)*(H$11/2-H$15)-H$12*M7*(H$11/2-H$16),IF(K7<=H$11,0.8*H$18*K7*H$10*(H$11/2-0.8*K7/2)+H$14*(O7-0.8*H$18)*(H$11/2-H$15)+H$12*M7*(H$11/2-H$16),H$18*(1-(1-0.8)*H$11/K7)*H$11*H$10*(H$11/2 -(1- (1-0.8)*H$11/K7)*H$11/2) + H$14*O7*(H$11/2-H$15)+H$12*M7*(H$11/2-H$16)))))) -> 11.689583 | R7: ='Moment resistant'!$H$14 -> 600.51 | S7: =IF(OR(AND(P7>=R7,P6<=R7),AND(P7<=R7,P6>=R7)),Q7+(Q6-Q7)*(P7-R7)/(P7-P6),"") | T7: =IF(OR(AND(P7>=R7,P6<=R7),AND(P7<=R7,P6>=R7)),K7+(K6-K7)*(P7-R7)/(P7-P6),"")
B8: 0.9 | C8: 1h<…< 24h | I8: -1 | J8: =IF(K8<=0,"Domaine 1",IF(AND(K8>0,K8<=$H$16*$H$21/($H$21+$H$20)),"Domaine 2",IF(K8<=$H$23,"Domaine 3",IF(K8<=$H$16,"Domaine 4",IF(K8<=$H$11,"Domaine 4a","Domaine 5"))))) -> Domaine 1 | K8: =I8*$H$16 -> -1.575 | L8: =IF(K8<=0,"N/A",IF(K8<=$H$16*$H$21/($H$21+$H$20),"N/A",IF(K8<=$H$23,$H$21 * ($H$16 - K8) /K8,IF(K8<=$H$16,$H$21 * ($H$16 - K8) /K8,IF(K8<=$H$11,$H$21 * (K8-$H$16) /K8,$H$22 * (K8 - $H$16) / (K8 -$H$11 / 2)))))) -> N/A | M8: =IF(L8="N/A","N/A",IF(L8>=0,MIN(L8*$H$17,$H$19),MAX(L8*$H$17,-$H$19))) -> N/A | N8: =IF(K8<=0,$H$20*($H$15-K8)/($H$16-K8),IF(K8<=$H$16*$H$21/($H$21+$H$20),$H$20*(K8-$H$15)/($H$16-K8),IF(K8<=$H$23,$H$20*(K8-$H$15)/K8,IF(K8<=$H$16,$H$20*(K8-$H$15)/K8,IF(K8<=$H$11,$H$20*(K8-$H$15)/K8,$H$22 * (K8 - $H$15) / (K8 - $H$11 / 2)))))) -> 0.0050793651 | O8: =IF(N8>=0,MIN(N8*$H$17,$H$19),MAX(N8*$H$17,-$H$19)) -> 400 | P8: =1000*IF(K8<0,-H$14*(O8-0.8*H$18)-H$12*H$19,IF(K8<=H$16*H$21/(H$21+H$20),0.8*H$18*K8*H$10+H$14*(O8-0.8*H$18)-H$12*H$19,IF(K8<=H$23,0.8*H$18*K8*H$10+H$14*(O8-0.8*H$18)-H$12*M8,IF(K8<=H$16,0.8*H$18*K8*H$10+H$14*(O8-0.8*H$18)-H$12*M8,IF(K8<=H$11,0.8*H$18*K8*H$10+H$14*(O8-0.8*H$18)+H$12*M8,H$18*(1-(1-0.8)*H$11/K8)*H$11*H$10+H$14*(O8-0.8*H$18)+H$12*M8))))) -> -708.91667 | Q8: =1000*IF(K8<0,-H$14*(O8-0.8*H$18)*(H$11/2-H$15)-H$12*H$19*(H$11/2-H$16),IF(K8<=H$16*H$21/(H$21+H$20),0.8*H$18*K8*H$10*(H$11/2-0.8*K8/2)+H$14*(O8-0.8*H$18)*(H$11/2-H$15)-H$12*H$19*(H$11/2-H$16),IF(K8<=H$23,0.8*H$18*K8*H$10*(H$11/2-0.8*K8/2)+H$14*(O8-0.8*H$18)*(H$11/2-H$15)-H$12*M8*(H$11/2-H$16),IF(K8<=H$16,0.8*H$18*K8*H$10*(H$11/2-0.8*K8/2)+H$14*(O8-0.8*H$18)*(H$11/2-H$15)-H$12*M8*(H$11/2-H$16),IF(K8<=H$11,0.8*H$18*K8*H$10*(H$11/2-0.8*K8/2)+H$14*(O8-0.8*H$18)*(H$11/2-H$15)+H$12*M8*(H$11/2-H$16),H$18*(1-(1-0.8)*H$11/K8)*H$11*H$10*(H$11/2 -(1- (1-0.8)*H$11/K8)*H$11/2) + H$14*O8*(H$11/2-H$15)+H$12*M8*(H$11/2-H$16)))))) -> 11.689583 | R8: ='Moment resistant'!$H$14 -> 600.51 | S8: =IF(OR(AND(P8>=R8,P7<=R8),AND(P8<=R8,P7>=R8)),Q8+(Q7-Q8)*(P8-R8)/(P8-P7),"") | T8: =IF(OR(AND(P8>=R8,P7<=R8),AND(P8<=R8,P7>=R8)),K8+(K7-K8)*(P8-R8)/(P8-P7),"")
B9: 0.85 | C9: < 1h | I9: -0.9 | J9: =IF(K9<=0,"Domaine 1",IF(AND(K9>0,K9<=$H$16*$H$21/($H$21+$H$20)),"Domaine 2",IF(K9<=$H$23,"Domaine 3",IF(K9<=$H$16,"Domaine 4",IF(K9<=$H$11,"Domaine 4a","Domaine 5"))))) -> Domaine 1 | K9: =I9*$H$16 -> -1.4175 | L9: =IF(K9<=0,"N/A",IF(K9<=$H$16*$H$21/($H$21+$H$20),"N/A",IF(K9<=$H$23,$H$21 * ($H$16 - K9) /K9,IF(K9<=$H$16,$H$21 * ($H$16 - K9) /K9,IF(K9<=$H$11,$H$21 * (K9-$H$16) /K9,$H$22 * (K9 - $H$16) / (K9 -$H$11 / 2)))))) -> N/A | M9: =IF(L9="N/A","N/A",IF(L9>=0,MIN(L9*$H$17,$H$19),MAX(L9*$H$17,-$H$19))) -> N/A | N9: =IF(K9<=0,$H$20*($H$15-K9)/($H$16-K9),IF(K9<=$H$16*$H$21/($H$21+$H$20),$H$20*(K9-$H$15)/($H$16-K9),IF(K9<=$H$23,$H$20*(K9-$H$15)/K9,IF(K9<=$H$16,$H$20*(K9-$H$15)/K9,IF(K9<=$H$11,$H$20*(K9-$H$15)/K9,$H$22 * (K9 - $H$15) / (K9 - $H$11 / 2)))))) -> 0.0048203843 | O9: =IF(N9>=0,MIN(N9*$H$17,$H$19),MAX(N9*$H$17,-$H$19)) -> 400 | P9: =1000*IF(K9<0,-H$14*(O9-0.8*H$18)-H$12*H$19,IF(K9<=H$16*H$21/(H$21+H$20),0.8*H$18*K9*H$10+H$14*(O9-0.8*H$18)-H$12*H$19,IF(K9<=H$23,0.8*H$18*K9*H$10+H$14*(O9-0.8*H$18)-H$12*M9,IF(K9<=H$16,0.8*H$18*K9*H$10+H$14*(O9-0.8*H$18)-H$12*M9,IF(K9<=H$11,0.8*H$18*K9*H$10+H$14*(O9-0.8*H$18)+H$12*M9,H$18*(1-(1-0.8)*H$11/K9)*H$11*H$10+H$14*(O9-0.8*H$18)+H$12*M9))))) -> -708.91667 | Q9: =1000*IF(K9<0,-H$14*(O9-0.8*H$18)*(H$11/2-H$15)-H$12*H$19*(H$11/2-H$16),IF(K9<=H$16*H$21/(H$21+H$20),0.8*H$18*K9*H$10*(H$11/2-0.8*K9/2)+H$14*(O9-0.8*H$18)*(H$11/2-H$15)-H$12*H$19*(H$11/2-H$16),IF(K9<=H$23,0.8*H$18*K9*H$10*(H$11/2-0.8*K9/2)+H$14*(O9-0.8*H$18)*(H$11/2-H$15)-H$12*M9*(H$11/2-H$16),IF(K9<=H$16,0.8*H$18*K9*H$10*(H$11/2-0.8*K9/2)+H$14*(O9-0.8*H$18)*(H$11/2-H$15)-H$12*M9*(H$11/2-H$16),IF(K9<=H$11,0.8*H$18*K9*H$10*(H$11/2-0.8*K9/2)+H$14*(O9-0.8*H$18)*(H$11/2-H$15)+H$12*M9*(H$11/2-H$16),H$18*(1-(1-0.8)*H$11/K9)*H$11*H$10*(H$11/2 -(1- (1-0.8)*H$11/K9)*H$11/2) + H$14*O9*(H$11/2-H$15)+H$12*M9*(H$11/2-H$16)))))) -> 11.689583 | R9: ='Moment resistant'!$H$14 -> 600.51 | S9: =IF(OR(AND(P9>=R9,P8<=R9),AND(P9<=R9,P8>=R9)),Q9+(Q8-Q9)*(P9-R9)/(P9-P8),"") | T9: =IF(OR(AND(P9>=R9,P8<=R9),AND(P9<=R9,P8>=R9)),K9+(K8-K9)*(P9-R9)/(P9-P8),"")
G10: b = | H10: ='Moment resistant'!$H$16/100 -> 0.2 | I10: -0.8 | J10: =IF(K10<=0,"Domaine 1",IF(AND(K10>0,K10<=$H$16*$H$21/($H$21+$H$20)),"Domaine 2",IF(K10<=$H$23,"Domaine 3",IF(K10<=$H$16,"Domaine 4",IF(K10<=$H$11,"Domaine 4a","Domaine 5"))))) -> Domaine 1 | K10: =I10*$H$16 -> -1.26 | L10: =IF(K10<=0,"N/A",IF(K10<=$H$16*$H$21/($H$21+$H$20),"N/A",IF(K10<=$H$23,$H$21 * ($H$16 - K10) /K10,IF(K10<=$H$16,$H$21 * ($H$16 - K10) /K10,IF(K10<=$H$11,$H$21 * (K10-$H$16) /K10,$H$22 * (K10 - $H$16) / (K10 -$H$11 / 2)))))) -> N/A | M10: =IF(L10="N/A","N/A",IF(L10>=0,MIN(L10*$H$17,$H$19),MAX(L10*$H$17,-$H$19))) -> N/A | N10: =IF(K10<=0,$H$20*($H$15-K10)/($H$16-K10),IF(K10<=$H$16*$H$21/($H$21+$H$20),$H$20*(K10-$H$15)/($H$16-K10),IF(K10<=$H$23,$H$20*(K10-$H$15)/K10,IF(K10<=$H$16,$H$20*(K10-$H$15)/K10,IF(K10<=$H$11,$H$20*(K10-$H$15)/K10,$H$22 * (K10 - $H$15) / (K10 - $H$11 / 2)))))) -> 0.0045326279 | O10: =IF(N10>=0,MIN(N10*$H$17,$H$19),MAX(N10*$H$17,-$H$19)) -> 400 | P10: =1000*IF(K10<0,-H$14*(O10-0.8*H$18)-H$12*H$19,IF(K10<=H$16*H$21/(H$21+H$20),0.8*H$18*K10*H$10+H$14*(O10-0.8*H$18)-H$12*H$19,IF(K10<=H$23,0.8*H$18*K10*H$10+H$14*(O10-0.8*H$18)-H$12*M10,IF(K10<=H$16,0.8*H$18*K10*H$10+H$14*(O10-0.8*H$18)-H$12*M10,IF(K10<=H$11,0.8*H$18*K10*H$10+H$14*(O10-0.8*H$18)+H$12*M10,H$18*(1-(1-0.8)*H$11/K10)*H$11*H$10+H$14*(O10-0.8*H$18)+H$12*M10))))) -> -708.91667 | Q10: =1000*IF(K10<0,-H$14*(O10-0.8*H$18)*(H$11/2-H$15)-H$12*H$19*(H$11/2-H$16),IF(K10<=H$16*H$21/(H$21+H$20),0.8*H$18*K10*H$10*(H$11/2-0.8*K10/2)+H$14*(O10-0.8*H$18)*(H$11/2-H$15)-H$12*H$19*(H$11/2-H$16),IF(K10<=H$23,0.8*H$18*K10*H$10*(H$11/2-0.8*K10/2)+H$14*(O10-0.8*H$18)*(H$11/2-H$15)-H$12*M10*(H$11/2-H$16),IF(K10<=H$16,0.8*H$18*K10*H$10*(H$11/2-0.8*K10/2)+H$14*(O10-0.8*H$18)*(H$11/2-H$15)-H$12*M10*(H$11/2-H$16),IF(K10<=H$11,0.8*H$18*K10*H$10*(H$11/2-0.8*K10/2)+H$14*(O10-0.8*H$18)*(H$11/2-H$15)+H$12*M10*(H$11/2-H$16),H$18*(1-(1-0.8)*H$11/K10)*H$11*H$10*(H$11/2 -(1- (1-0.8)*H$11/K10)*H$11/2) + H$14*O10*(H$11/2-H$15)+H$12*M10*(H$11/2-H$16)))))) -> 11.689583 | R10: ='Moment resistant'!$H$14 -> 600.51 | S10: =IF(OR(AND(P10>=R10,P9<=R10),AND(P10<=R10,P9>=R10)),Q10+(Q9-Q10)*(P10-R10)/(P10-P9),"") | T10: =IF(OR(AND(P10>=R10,P9<=R10),AND(P10<=R10,P9>=R10)),K10+(K9-K10)*(P10-R10)/(P10-P9),"")
B11: Coefficient de sécurite - Béton | G11: h = | H11: ='Moment resistant'!$H$17/100 -> 1.6 | I11: -0.7 | J11: =IF(K11<=0,"Domaine 1",IF(AND(K11>0,K11<=$H$16*$H$21/($H$21+$H$20)),"Domaine 2",IF(K11<=$H$23,"Domaine 3",IF(K11<=$H$16,"Domaine 4",IF(K11<=$H$11,"Domaine 4a","Domaine 5"))))) -> Domaine 1 | K11: =I11*$H$16 -> -1.1025 | L11: =IF(K11<=0,"N/A",IF(K11<=$H$16*$H$21/($H$21+$H$20),"N/A",IF(K11<=$H$23,$H$21 * ($H$16 - K11) /K11,IF(K11<=$H$16,$H$21 * ($H$16 - K11) /K11,IF(K11<=$H$11,$H$21 * (K11-$H$16) /K11,$H$22 * (K11 - $H$16) / (K11 -$H$11 / 2)))))) -> N/A | M11: =IF(L11="N/A","N/A",IF(L11>=0,MIN(L11*$H$17,$H$19),MAX(L11*$H$17,-$H$19))) -> N/A | N11: =IF(K11<=0,$H$20*($H$15-K11)/($H$16-K11),IF(K11<=$H$16*$H$21/($H$21+$H$20),$H$20*(K11-$H$15)/($H$16-K11),IF(K11<=$H$23,$H$20*(K11-$H$15)/K11,IF(K11<=$H$16,$H$20*(K11-$H$15)/K11,IF(K11<=$H$11,$H$20*(K11-$H$15)/K11,$H$22 * (K11 - $H$15) / (K11 - $H$11 / 2)))))) -> 0.0042110177 | O11: =IF(N11>=0,MIN(N11*$H$17,$H$19),MAX(N11*$H$17,-$H$19)) -> 400 | P11: =1000*IF(K11<0,-H$14*(O11-0.8*H$18)-H$12*H$19,IF(K11<=H$16*H$21/(H$21+H$20),0.8*H$18*K11*H$10+H$14*(O11-0.8*H$18)-H$12*H$19,IF(K11<=H$23,0.8*H$18*K11*H$10+H$14*(O11-0.8*H$18)-H$12*M11,IF(K11<=H$16,0.8*H$18*K11*H$10+H$14*(O11-0.8*H$18)-H$12*M11,IF(K11<=H$11,0.8*H$18*K11*H$10+H$14*(O11-0.8*H$18)+H$12*M11,H$18*(1-(1-0.8)*H$11/K11)*H$11*H$10+H$14*(O11-0.8*H$18)+H$12*M11))))) -> -708.91667 | Q11: =1000*IF(K11<0,-H$14*(O11-0.8*H$18)*(H$11/2-H$15)-H$12*H$19*(H$11/2-H$16),IF(K11<=H$16*H$21/(H$21+H$20),0.8*H$18*K11*H$10*(H$11/2-0.8*K11/2)+H$14*(O11-0.8*H$18)*(H$11/2-H$15)-H$12*H$19*(H$11/2-H$16),IF(K11<=H$23,0.8*H$18*K11*H$10*(H$11/2-0.8*K11/2)+H$14*(O11-0.8*H$18)*(H$11/2-H$15)-H$12*M11*(H$11/2-H$16),IF(K11<=H$16,0.8*H$18*K11*H$10*(H$11/2-0.8*K11/2)+H$14*(O11-0.8*H$18)*(H$11/2-H$15)-H$12*M11*(H$11/2-H$16),IF(K11<=H$11,0.8*H$18*K11*H$10*(H$11/2-0.8*K11/2)+H$14*(O11-0.8*H$18)*(H$11/2-H$15)+H$12*M11*(H$11/2-H$16),H$18*(1-(1-0.8)*H$11/K11)*H$11*H$10*(H$11/2 -(1- (1-0.8)*H$11/K11)*H$11/2) + H$14*O11*(H$11/2-H$15)+H$12*M11*(H$11/2-H$16)))))) -> 11.689583 | R11: ='Moment resistant'!$H$14 -> 600.51 | S11: =IF(OR(AND(P11>=R11,P10<=R11),AND(P11<=R11,P10>=R11)),Q11+(Q10-Q11)*(P11-R11)/(P11-P10),"") | T11: =IF(OR(AND(P11>=R11,P10<=R11),AND(P11<=R11,P10>=R11)),K11+(K10-K11)*(P11-R11)/(P11-P10),"")
B12: 1.5 | G12: As1 = | H12: =0.0001*'Moment resistant'!$H$18 -> 0.000905 | I12: -0.6 | J12: =IF(K12<=0,"Domaine 1",IF(AND(K12>0,K12<=$H$16*$H$21/($H$21+$H$20)),"Domaine 2",IF(K12<=$H$23,"Domaine 3",IF(K12<=$H$16,"Domaine 4",IF(K12<=$H$11,"Domaine 4a","Domaine 5"))))) -> Domaine 1 | K12: =I12*$H$16 -> -0.945 | L12: =IF(K12<=0,"N/A",IF(K12<=$H$16*$H$21/($H$21+$H$20),"N/A",IF(K12<=$H$23,$H$21 * ($H$16 - K12) /K12,IF(K12<=$H$16,$H$21 * ($H$16 - K12) /K12,IF(K12<=$H$11,$H$21 * (K12-$H$16) /K12,$H$22 * (K12 - $H$16) / (K12 -$H$11 / 2)))))) -> N/A | M12: =IF(L12="N/A","N/A",IF(L12>=0,MIN(L12*$H$17,$H$19),MAX(L12*$H$17,-$H$19))) -> N/A | N12: =IF(K12<=0,$H$20*($H$15-K12)/($H$16-K12),IF(K12<=$H$16*$H$21/($H$21+$H$20),$H$20*(K12-$H$15)/($H$16-K12),IF(K12<=$H$23,$H$20*(K12-$H$15)/K12,IF(K12<=$H$16,$H$20*(K12-$H$15)/K12,IF(K12<=$H$11,$H$20*(K12-$H$15)/K12,$H$22 * (K12 - $H$15) / (K12 - $H$11 / 2)))))) -> 0.0038492063 | O12: =IF(N12>=0,MIN(N12*$H$17,$H$19),MAX(N12*$H$17,-$H$19)) -> 400 | P12: =1000*IF(K12<0,-H$14*(O12-0.8*H$18)-H$12*H$19,IF(K12<=H$16*H$21/(H$21+H$20),0.8*H$18*K12*H$10+H$14*(O12-0.8*H$18)-H$12*H$19,IF(K12<=H$23,0.8*H$18*K12*H$10+H$14*(O12-0.8*H$18)-H$12*M12,IF(K12<=H$16,0.8*H$18*K12*H$10+H$14*(O12-0.8*H$18)-H$12*M12,IF(K12<=H$11,0.8*H$18*K12*H$10+H$14*(O12-0.8*H$18)+H$12*M12,H$18*(1-(1-0.8)*H$11/K12)*H$11*H$10+H$14*(O12-0.8*H$18)+H$12*M12))))) -> -708.91667 | Q12: =1000*IF(K12<0,-H$14*(O12-0.8*H$18)*(H$11/2-H$15)-H$12*H$19*(H$11/2-H$16),IF(K12<=H$16*H$21/(H$21+H$20),0.8*H$18*K12*H$10*(H$11/2-0.8*K12/2)+H$14*(O12-0.8*H$18)*(H$11/2-H$15)-H$12*H$19*(H$11/2-H$16),IF(K12<=H$23,0.8*H$18*K12*H$10*(H$11/2-0.8*K12/2)+H$14*(O12-0.8*H$18)*(H$11/2-H$15)-H$12*M12*(H$11/2-H$16),IF(K12<=H$16,0.8*H$18*K12*H$10*(H$11/2-0.8*K12/2)+H$14*(O12-0.8*H$18)*(H$11/2-H$15)-H$12*M12*(H$11/2-H$16),IF(K12<=H$11,0.8*H$18*K12*H$10*(H$11/2-0.8*K12/2)+H$14*(O12-0.8*H$18)*(H$11/2-H$15)+H$12*M12*(H$11/2-H$16),H$18*(1-(1-0.8)*H$11/K12)*H$11*H$10*(H$11/2 -(1- (1-0.8)*H$11/K12)*H$11/2) + H$14*O12*(H$11/2-H$15)+H$12*M12*(H$11/2-H$16)))))) -> 11.689583 | R12: ='Moment resistant'!$H$14 -> 600.51 | S12: =IF(OR(AND(P12>=R12,P11<=R12),AND(P12<=R12,P11>=R12)),Q12+(Q11-Q12)*(P12-R12)/(P12-P11),"") | T12: =IF(OR(AND(P12>=R12,P11<=R12),AND(P12<=R12,P11>=R12)),K12+(K11-K12)*(P12-R12)/(P12-P11),"")
B13: 1.2 | G13: c = | H13: =0.01*'Moment resistant'!$H$19 -> 0.025 | I13: -0.5 | J13: =IF(K13<=0,"Domaine 1",IF(AND(K13>0,K13<=$H$16*$H$21/($H$21+$H$20)),"Domaine 2",IF(K13<=$H$23,"Domaine 3",IF(K13<=$H$16,"Domaine 4",IF(K13<=$H$11,"Domaine 4a","Domaine 5"))))) -> Domaine 1 | K13: =I13*$H$16 -> -0.7875 | L13: =IF(K13<=0,"N/A",IF(K13<=$H$16*$H$21/($H$21+$H$20),"N/A",IF(K13<=$H$23,$H$21 * ($H$16 - K13) /K13,IF(K13<=$H$16,$H$21 * ($H$16 - K13) /K13,IF(K13<=$H$11,$H$21 * (K13-$H$16) /K13,$H$22 * (K13 - $H$16) / (K13 -$H$11 / 2)))))) -> N/A | M13: =IF(L13="N/A","N/A",IF(L13>=0,MIN(L13*$H$17,$H$19),MAX(L13*$H$17,-$H$19))) -> N/A | N13: =IF(K13<=0,$H$20*($H$15-K13)/($H$16-K13),IF(K13<=$H$16*$H$21/($H$21+$H$20),$H$20*(K13-$H$15)/($H$16-K13),IF(K13<=$H$23,$H$20*(K13-$H$15)/K13,IF(K13<=$H$16,$H$20*(K13-$H$15)/K13,IF(K13<=$H$11,$H$20*(K13-$H$15)/K13,$H$22 * (K13 - $H$15) / (K13 - $H$11 / 2)))))) -> 0.0034391534 | O13: =IF(N13>=0,MIN(N13*$H$17,$H$19),MAX(N13*$H$17,-$H$19)) -> 400 | P13: =1000*IF(K13<0,-H$14*(O13-0.8*H$18)-H$12*H$19,IF(K13<=H$16*H$21/(H$21+H$20),0.8*H$18*K13*H$10+H$14*(O13-0.8*H$18)-H$12*H$19,IF(K13<=H$23,0.8*H$18*K13*H$10+H$14*(O13-0.8*H$18)-H$12*M13,IF(K13<=H$16,0.8*H$18*K13*H$10+H$14*(O13-0.8*H$18)-H$12*M13,IF(K13<=H$11,0.8*H$18*K13*H$10+H$14*(O13-0.8*H$18)+H$12*M13,H$18*(1-(1-0.8)*H$11/K13)*H$11*H$10+H$14*(O13-0.8*H$18)+H$12*M13))))) -> -708.91667 | Q13: =1000*IF(K13<0,-H$14*(O13-0.8*H$18)*(H$11/2-H$15)-H$12*H$19*(H$11/2-H$16),IF(K13<=H$16*H$21/(H$21+H$20),0.8*H$18*K13*H$10*(H$11/2-0.8*K13/2)+H$14*(O13-0.8*H$18)*(H$11/2-H$15)-H$12*H$19*(H$11/2-H$16),IF(K13<=H$23,0.8*H$18*K13*H$10*(H$11/2-0.8*K13/2)+H$14*(O13-0.8*H$18)*(H$11/2-H$15)-H$12*M13*(H$11/2-H$16),IF(K13<=H$16,0.8*H$18*K13*H$10*(H$11/2-0.8*K13/2)+H$14*(O13-0.8*H$18)*(H$11/2-H$15)-H$12*M13*(H$11/2-H$16),IF(K13<=H$11,0.8*H$18*K13*H$10*(H$11/2-0.8*K13/2)+H$14*(O13-0.8*H$18)*(H$11/2-H$15)+H$12*M13*(H$11/2-H$16),H$18*(1-(1-0.8)*H$11/K13)*H$11*H$10*(H$11/2 -(1- (1-0.8)*H$11/K13)*H$11/2) + H$14*O13*(H$11/2-H$15)+H$12*M13*(H$11/2-H$16)))))) -> 11.689583 | R13: ='Moment resistant'!$H$14 -> 600.51 | S13: =IF(OR(AND(P13>=R13,P12<=R13),AND(P13<=R13,P12>=R13)),Q13+(Q12-Q13)*(P13-R13)/(P13-P12),"") | T13: =IF(OR(AND(P13>=R13,P12<=R13),AND(P13<=R13,P12>=R13)),K13+(K12-K13)*(P13-R13)/(P13-P12),"")
G14: As2 = | H14: =0.0001*'Moment resistant'!$H$20 -> 0.000905 | I14: -0.4 | J14: =IF(K14<=0,"Domaine 1",IF(AND(K14>0,K14<=$H$16*$H$21/($H$21+$H$20)),"Domaine 2",IF(K14<=$H$23,"Domaine 3",IF(K14<=$H$16,"Domaine 4",IF(K14<=$H$11,"Domaine 4a","Domaine 5"))))) -> Domaine 1 | K14: =I14*$H$16 -> -0.63 | L14: =IF(K14<=0,"N/A",IF(K14<=$H$16*$H$21/($H$21+$H$20),"N/A",IF(K14<=$H$23,$H$21 * ($H$16 - K14) /K14,IF(K14<=$H$16,$H$21 * ($H$16 - K14) /K14,IF(K14<=$H$11,$H$21 * (K14-$H$16) /K14,$H$22 * (K14 - $H$16) / (K14 -$H$11 / 2)))))) -> N/A | M14: =IF(L14="N/A","N/A",IF(L14>=0,MIN(L14*$H$17,$H$19),MAX(L14*$H$17,-$H$19))) -> N/A | N14: =IF(K14<=0,$H$20*($H$15-K14)/($H$16-K14),IF(K14<=$H$16*$H$21/($H$21+$H$20),$H$20*(K14-$H$15)/($H$16-K14),IF(K14<=$H$23,$H$20*(K14-$H$15)/K14,IF(K14<=$H$16,$H$20*(K14-$H$15)/K14,IF(K14<=$H$11,$H$20*(K14-$H$15)/K14,$H$22 * (K14 - $H$15) / (K14 - $H$11 / 2)))))) -> 0.0029705215 | O14: =IF(N14>=0,MIN(N14*$H$17,$H$19),MAX(N14*$H$17,-$H$19)) -> 400 | P14: =1000*IF(K14<0,-H$14*(O14-0.8*H$18)-H$12*H$19,IF(K14<=H$16*H$21/(H$21+H$20),0.8*H$18*K14*H$10+H$14*(O14-0.8*H$18)-H$12*H$19,IF(K14<=H$23,0.8*H$18*K14*H$10+H$14*(O14-0.8*H$18)-H$12*M14,IF(K14<=H$16,0.8*H$18*K14*H$10+H$14*(O14-0.8*H$18)-H$12*M14,IF(K14<=H$11,0.8*H$18*K14*H$10+H$14*(O14-0.8*H$18)+H$12*M14,H$18*(1-(1-0.8)*H$11/K14)*H$11*H$10+H$14*(O14-0.8*H$18)+H$12*M14))))) -> -708.91667 | Q14: =1000*IF(K14<0,-H$14*(O14-0.8*H$18)*(H$11/2-H$15)-H$12*H$19*(H$11/2-H$16),IF(K14<=H$16*H$21/(H$21+H$20),0.8*H$18*K14*H$10*(H$11/2-0.8*K14/2)+H$14*(O14-0.8*H$18)*(H$11/2-H$15)-H$12*H$19*(H$11/2-H$16),IF(K14<=H$23,0.8*H$18*K14*H$10*(H$11/2-0.8*K14/2)+H$14*(O14-0.8*H$18)*(H$11/2-H$15)-H$12*M14*(H$11/2-H$16),IF(K14<=H$16,0.8*H$18*K14*H$10*(H$11/2-0.8*K14/2)+H$14*(O14-0.8*H$18)*(H$11/2-H$15)-H$12*M14*(H$11/2-H$16),IF(K14<=H$11,0.8*H$18*K14*H$10*(H$11/2-0.8*K14/2)+H$14*(O14-0.8*H$18)*(H$11/2-H$15)+H$12*M14*(H$11/2-H$16),H$18*(1-(1-0.8)*H$11/K14)*H$11*H$10*(H$11/2 -(1- (1-0.8)*H$11/K14)*H$11/2) + H$14*O14*(H$11/2-H$15)+H$12*M14*(H$11/2-H$16)))))) -> 11.689583 | R14: ='Moment resistant'!$H$14 -> 600.51 | S14: =IF(OR(AND(P14>=R14,P13<=R14),AND(P14<=R14,P13>=R14)),Q14+(Q13-Q14)*(P14-R14)/(P14-P13),"") | T14: =IF(OR(AND(P14>=R14,P13<=R14),AND(P14<=R14,P13>=R14)),K14+(K13-K14)*(P14-R14)/(P14-P13),"")
B15: Coefficient de sécurite - Acier | G15: Cs = | H15: =0.01*'Moment resistant'!$H$21 -> 0.025 | I15: -0.3 | J15: =IF(K15<=0,"Domaine 1",IF(AND(K15>0,K15<=$H$16*$H$21/($H$21+$H$20)),"Domaine 2",IF(K15<=$H$23,"Domaine 3",IF(K15<=$H$16,"Domaine 4",IF(K15<=$H$11,"Domaine 4a","Domaine 5"))))) -> Domaine 1 | K15: =I15*$H$16 -> -0.4725 | L15: =IF(K15<=0,"N/A",IF(K15<=$H$16*$H$21/($H$21+$H$20),"N/A",IF(K15<=$H$23,$H$21 * ($H$16 - K15) /K15,IF(K15<=$H$16,$H$21 * ($H$16 - K15) /K15,IF(K15<=$H$11,$H$21 * (K15-$H$16) /K15,$H$22 * (K15 - $H$16) / (K15 -$H$11 / 2)))))) -> N/A | M15: =IF(L15="N/A","N/A",IF(L15>=0,MIN(L15*$H$17,$H$19),MAX(L15*$H$17,-$H$19))) -> N/A | N15: =IF(K15<=0,$H$20*($H$15-K15)/($H$16-K15),IF(K15<=$H$16*$H$21/($H$21+$H$20),$H$20*(K15-$H$15)/($H$16-K15),IF(K15<=$H$23,$H$20*(K15-$H$15)/K15,IF(K15<=$H$16,$H$20*(K15-$H$15)/K15,IF(K15<=$H$11,$H$20*(K15-$H$15)/K15,$H$22 * (K15 - $H$15) / (K15 - $H$11 / 2)))))) -> 0.0024297924 | O15: =IF(N15>=0,MIN(N15*$H$17,$H$19),MAX(N15*$H$17,-$H$19)) -> 400 | P15: =1000*IF(K15<0,-H$14*(O15-0.8*H$18)-H$12*H$19,IF(K15<=H$16*H$21/(H$21+H$20),0.8*H$18*K15*H$10+H$14*(O15-0.8*H$18)-H$12*H$19,IF(K15<=H$23,0.8*H$18*K15*H$10+H$14*(O15-0.8*H$18)-H$12*M15,IF(K15<=H$16,0.8*H$18*K15*H$10+H$14*(O15-0.8*H$18)-H$12*M15,IF(K15<=H$11,0.8*H$18*K15*H$10+H$14*(O15-0.8*H$18)+H$12*M15,H$18*(1-(1-0.8)*H$11/K15)*H$11*H$10+H$14*(O15-0.8*H$18)+H$12*M15))))) -> -708.91667 | Q15: =1000*IF(K15<0,-H$14*(O15-0.8*H$18)*(H$11/2-H$15)-H$12*H$19*(H$11/2-H$16),IF(K15<=H$16*H$21/(H$21+H$20),0.8*H$18*K15*H$10*(H$11/2-0.8*K15/2)+H$14*(O15-0.8*H$18)*(H$11/2-H$15)-H$12*H$19*(H$11/2-H$16),IF(K15<=H$23,0.8*H$18*K15*H$10*(H$11/2-0.8*K15/2)+H$14*(O15-0.8*H$18)*(H$11/2-H$15)-H$12*M15*(H$11/2-H$16),IF(K15<=H$16,0.8*H$18*K15*H$10*(H$11/2-0.8*K15/2)+H$14*(O15-0.8*H$18)*(H$11/2-H$15)-H$12*M15*(H$11/2-H$16),IF(K15<=H$11,0.8*H$18*K15*H$10*(H$11/2-0.8*K15/2)+H$14*(O15-0.8*H$18)*(H$11/2-H$15)+H$12*M15*(H$11/2-H$16),H$18*(1-(1-0.8)*H$11/K15)*H$11*H$10*(H$11/2 -(1- (1-0.8)*H$11/K15)*H$11/2) + H$14*O15*(H$11/2-H$15)+H$12*M15*(H$11/2-H$16)))))) -> 11.689583 | R15: ='Moment resistant'!$H$14 -> 600.51 | S15: =IF(OR(AND(P15>=R15,P14<=R15),AND(P15<=R15,P14>=R15)),Q15+(Q14-Q15)*(P15-R15)/(P15-P14),"") | T15: =IF(OR(AND(P15>=R15,P14<=R15),AND(P15<=R15,P14>=R15)),K15+(K14-K15)*(P15-R15)/(P15-P14),"")
